Workbook

Sheet Лист1
B1: 1 | C1: 2 | D1: 3 | E1: 4 | F1: 5 | G1: 6 | H1: 7 | I1: 8 | J1: 9 | K1: 10 | L1: 11 | M1: 12 | N1: 13 | O1: 14 | P1: 15 | Q1: 16 | R1: 17 | S1: 18 | T1: 19 | U1: 20 | V1: 21 | W1: 22 | X1: 23 | Y1: 24 | Z1: 25 | AA1: 26 | AB1: 27 | AC1: 28 | AD1: 29 | AE1: 30 | AF1: 31 | AG1: 32 | AH1: 33 | AI1: 34 | AJ1: 35 | AK1: 36 | AL1: 37 | AM1: 38 | AN1: 39 | AO1: 40 | AP1: 41 | AQ1: 42 | AR1: 43 | AS1: 44 | AT1: 45 | AU1: 46 | AV1: 47 | AW1: 48 | AX1: 49 | AY1: 50 | AZ1: 51 | BA1: 52 | BB1: 53 | BC1: 54 | BD1: 55 | BE1: 56 | BF1: 57 | BG1: 58 | BH1: 59 | BI1: 60 | BJ1: 61 | BK1: 62 | BL1: 63 | BM1: 64 | BN1: 65 | BO1: 66 | BP1: 67 | BQ1: 68 | BR1: 69 | BS1: 70 | BT1: 71 | BU1: 72 | BV1: 73 | BW1: 74 | BX1: 75 | BY1: 76 | BZ1: 77 | CA1: 78 | CB1: 79 | CC1: 80 | CD1: 81 | CE1: 82 | CF1: 83 | CG1: 84 | CH1: 85 | CI1: 86 | CJ1: 87 | CK1: 88 | CL1: 89 | CM1: 90 | CN1: 91 | CO1: 92 | CP1: 93 | CQ1: 94 | CR1: 95 | CS1: 96 | CT1: 97 | CU1: 98 | CV1: 99 | CW1: 100 | CX1: 101 | CY1: 102 | CZ1: 103 | DA1: 104 | DB1: 105 | DC1: 106 | DD1: 107 | DE1: 108 | DF1: 109 | DG1: 110 | DH1: 111 | DI1: 112 | DJ1: 113 | DK1: 114 | DL1: 115 | DM1: 116 | DN1: 117 | DO1: 118 | DP1: 119 | DQ1: 120 | DR1: 121 | DS1: 122 | DT1: 123 | DU1: 124 | DV1: 125 | DW1: 126 | DX1: 127 | DY1: 128 | DZ1: 129 | EA1: 130 | EB1: 131 | EC1: 132 | ED1: 133 | EE1: 134 | EF1: 135 | EG1: 136 | EH1: 137 | EI1: 138 | EJ1: 139 | EK1: 140 | EL1: 141 | EM1: 142 | EN1: 143 | EO1: 144 | EP1: 145 | EQ1: 146 | ER1: 147 | ES1: 148 | ET1: 149 | EU1: 150 | EV1: 151 | EW1: 152 | EX1: 153 | EY1: 154 | EZ1: 155 | FA1: 156 | FB1: 157 | FC1: 158 | FD1: 159 | FE1: 160 | FF1: 161 | FG1: 162 | FH1: 163 | FI1: 164 | FJ1: 165 | FK1: 166 | FL1: 167 | FM1: 168 | FN1: 169 | FO1: 170 | FP1: 171 | FQ1: 172 | FR1: 173 | FS1: 174 | FT1: 175 | FU1: 176 | FV1: 177 | FW1: 178 | FX1: 179 | FY1: 180 | FZ1: 181 | GA1: 182 | GB1: 183 | GC1: 184 | GD1: 185 | GE1: 186 | GF1: 187 | GG1: 188 | GH1: 189 | GI1: 190 | GJ1: 191 | GK1: 192 | GL1: 193 | GM1: 194 | GN1: 195 | GO1: 196 | GP1: 197 | GQ1: 198 | GR1: 199 | GS1: 200 | GT1: 201 | GU1: 202 | GV1: 203 | GW1: 204 | GX1: 205 | GY1: 206 | GZ1: 207 | HA1: 208 | HB1: 209 | HC1: 210 | HD1: 211 | HE1: 212 | HF1: 213 | HG1: 214 | HH1: 215 | HI1: 216 | HJ1: 217 | HK1: 218 | HL1: 219 | HM1: 220 | HN1: 221 | HO1: 222 | HP1: 223 | HQ1: 224 | HR1: 225 | HS1: 226
A2: 1 | B2: =IF(д!B2=0,IF(AND(INDEX($B$2:$HS$227,$A2+1,B$1)>0,INDEX($B$2:$HS$227,$A2,B$1+1)>0,INDEX($B$2:$HS$227,$A2*2,B$1)>0,INDEX($B$2:$HS$227,$A2,B$1*2)>0),-2,0) ,д!B2) -> 0 | C2: =IF(д!C2=0,IF(AND(INDEX($B$2:$HS$227,$A2+1,C$1)>0,INDEX($B$2:$HS$227,$A2,C$1+1)>0,INDEX($B$2:$HS$227,$A2*2,C$1)>0,INDEX($B$2:$HS$227,$A2,C$1*2)>0),-2,0) ,д!C2) -> 0 | D2: =IF(д!D2=0,IF(AND(INDEX($B$2:$HS$227,$A2+1,D$1)>0,INDEX($B$2:$HS$227,$A2,D$1+1)>0,INDEX($B$2:$HS$227,$A2*2,D$1)>0,INDEX($B$2:$HS$227,$A2,D$1*2)>0),-2,0) ,д!D2) -> 0 | E2: =IF(д!E2=0,IF(AND(INDEX($B$2:$HS$227,$A2+1,E$1)>0,INDEX($B$2:$HS$227,$A2,E$1+1)>0,INDEX($B$2:$HS$227,$A2*2,E$1)>0,INDEX($B$2:$HS$227,$A2,E$1*2)>0),-2,0) ,д!E2) -> 0 | F2: =IF(д!F2=0,IF(AND(INDEX($B$2:$HS$227,$A2+1,F$1)>0,INDEX($B$2:$HS$227,$A2,F$1+1)>0,INDEX($B$2:$HS$227,$A2*2,F$1)>0,INDEX($B$2:$HS$227,$A2,F$1*2)>0),-2,0) ,д!F2) -> 0 | G2: =IF(д!G2=0,IF(AND(INDEX($B$2:$HS$227,$A2+1,G$1)>0,INDEX($B$2:$HS$227,$A2,G$1+1)>0,INDEX($B$2:$HS$227,$A2*2,G$1)>0,INDEX($B$2:$HS$227,$A2,G$1*2)>0),-2,0) ,д!G2) -> 0 | H2: =IF(д!H2=0,IF(AND(INDEX($B$2:$HS$227,$A2+1,H$1)>0,INDEX($B$2:$HS$227,$A2,H$1+1)>0,INDEX($B$2:$HS$227,$A2*2,H$1)>0,INDEX($B$2:$HS$227,$A2,H$1*2)>0),-2,0) ,д!H2) -> 0 | I2: =IF(д!I2=0,IF(AND(INDEX($B$2:$HS$227,$A2+1,I$1)>0,INDEX($B$2:$HS$227,$A2,I$1+1)>0,INDEX($B$2:$HS$227,$A2*2,I$1)>0,INDEX($B$2:$HS$227,$A2,I$1*2)>0),-2,0) ,д!I2) -> 0 | ... DI2: =IF(д!DI2=0,IF(AND(INDEX($B$2:$HS$227,$A2+1,DI$1)>0,INDEX($B$2:$HS$227,$A2,DI$1+1)>0,INDEX($B$2:$HS$227,$A2*2,DI$1)>0,INDEX($B$2:$HS$227,$A2,DI$1*2)>0),-2,0) ,д!DI2) -> 2 | DJ2: =IF(д!DJ2=0,IF(OR(INDEX($B$2:$HS$227,$A2+1,DJ$1)<0,INDEX($B$2:$HS$227,$A2,DJ$1+1)<0,INDEX($B$2:$HS$227,$A2*2,DJ$1)<0,INDEX($B$2:$HS$227,$A2,DJ$1*2)<0),2,0) ,д!DJ2) -> 1 | DK2: =IF(д!DK2=0,IF(OR(INDEX($B$2:$HS$227,$A2+1,DK$1)>0,INDEX($B$2:$HS$227,$A2,DK$1+1)>0,INDEX($B$2:$HS$227,$A2*2,DK$1)>0,INDEX($B$2:$HS$227,$A2,DK$1*2)>0),-1,0) ,д!DK2) -> 1 | DL2: =IF(MAX(DL$1,$A2)*2 + MIN(DL$1,$A2) >= 227,1,0) -> 1 | DM2: =IF(MAX(DM$1,$A2)*2 + MIN(DM$1,$A2) >= 227,1,0) -> 1 | DN2: =IF(MAX(DN$1,$A2)*2 + MIN(DN$1,$A2) >= 227,1,0) -> 1 | DO2: =IF(MAX(DO$1,$A2)*2 + MIN(DO$1,$A2) >= 227,1,0) -> 1 | DP2: =IF(MAX(DP$1,$A2)*2 + MIN(DP$1,$A2) >= 227,1,0) -> 1 | DQ2: =IF(MAX(DQ$1,$A2)*2 + MIN(DQ$1,$A2) >= 227,1,0) -> 1 | DR2: =IF(MAX(DR$1,$A2)*2 + MIN(DR$1,$A2) >= 227,1,0) -> 1 | DS2: =IF(MAX(DS$1,$A2)*2 + MIN(DS$1,$A2) >= 227,1,0) -> 1 | ... HS2: =IF(MAX(HS$1,$A2)*2 + MIN(HS$1,$A2) >= 227,1,0) -> 1
A3: 2 | B3: =IF(д!B3=0,IF(AND(INDEX($B$2:$HS$227,$A3+1,B$1)>0,INDEX($B$2:$HS$227,$A3,B$1+1)>0,INDEX($B$2:$HS$227,$A3*2,B$1)>0,INDEX($B$2:$HS$227,$A3,B$1*2)>0),-2,0) ,д!B3) -> 0 | C3: =IF(д!C3=0,IF(AND(INDEX($B$2:$HS$227,$A3+1,C$1)>0,INDEX($B$2:$HS$227,$A3,C$1+1)>0,INDEX($B$2:$HS$227,$A3*2,C$1)>0,INDEX($B$2:$HS$227,$A3,C$1*2)>0),-2,0) ,д!C3) -> 0 | D3: =IF(д!D3=0,IF(AND(INDEX($B$2:$HS$227,$A3+1,D$1)>0,INDEX($B$2:$HS$227,$A3,D$1+1)>0,INDEX($B$2:$HS$227,$A3*2,D$1)>0,INDEX($B$2:$HS$227,$A3,D$1*2)>0),-2,0) ,д!D3) -> 0 | E3: =IF(д!E3=0,IF(AND(INDEX($B$2:$HS$227,$A3+1,E$1)>0,INDEX($B$2:$HS$227,$A3,E$1+1)>0,INDEX($B$2:$HS$227,$A3*2,E$1)>0,INDEX($B$2:$HS$227,$A3,E$1*2)>0),-2,0) ,д!E3) -> 0 | F3: =IF(д!F3=0,IF(AND(INDEX($B$2:$HS$227,$A3+1,F$1)>0,INDEX($B$2:$HS$227,$A3,F$1+1)>0,INDEX($B$2:$HS$227,$A3*2,F$1)>0,INDEX($B$2:$HS$227,$A3,F$1*2)>0),-2,0) ,д!F3) -> 0 | G3: =IF(д!G3=0,IF(AND(INDEX($B$2:$HS$227,$A3+1,G$1)>0,INDEX($B$2:$HS$227,$A3,G$1+1)>0,INDEX($B$2:$HS$227,$A3*2,G$1)>0,INDEX($B$2:$HS$227,$A3,G$1*2)>0),-2,0) ,д!G3) -> 0 | H3: =IF(д!H3=0,IF(AND(INDEX($B$2:$HS$227,$A3+1,H$1)>0,INDEX($B$2:$HS$227,$A3,H$1+1)>0,INDEX($B$2:$HS$227,$A3*2,H$1)>0,INDEX($B$2:$HS$227,$A3,H$1*2)>0),-2,0) ,д!H3) -> 0 | I3: =IF(д!I3=0,IF(AND(INDEX($B$2:$HS$227,$A3+1,I$1)>0,INDEX($B$2:$HS$227,$A3,I$1+1)>0,INDEX($B$2:$HS$227,$A3*2,I$1)>0,INDEX($B$2:$HS$227,$A3,I$1*2)>0),-2,0) ,д!I3) -> 0 | ... DI3: =IF(д!DI3=0,IF(AND(INDEX($B$2:$HS$227,$A3+1,DI$1)>0,INDEX($B$2:$HS$227,$A3,DI$1+1)>0,INDEX($B$2:$HS$227,$A3*2,DI$1)>0,INDEX($B$2:$HS$227,$A3,DI$1*2)>0),-2,0) ,д!DI3) -> -1 | DJ3: =IF(д!DJ3=0,IF(OR(INDEX($B$2:$HS$227,$A3+1,DJ$1)<0,INDEX($B$2:$HS$227,$A3,DJ$1+1)<0,INDEX($B$2:$HS$227,$A3*2,DJ$1)<0,INDEX($B$2:$HS$227,$A3,DJ$1*2)<0),2,0) ,д!DJ3) -> 1 | DK3: =IF(д!DK3=0,IF(OR(INDEX($B$2:$HS$227,$A3+1,DK$1)>0,INDEX($B$2:$HS$227,$A3,DK$1+1)>0,INDEX($B$2:$HS$227,$A3*2,DK$1)>0,INDEX($B$2:$HS$227,$A3,DK$1*2)>0),-1,0) ,д!DK3) -> 1 | DL3: =IF(MAX(DL$1,$A3)*2 + MIN(DL$1,$A3) >= 227,1,0) -> 1 | DM3: =IF(MAX(DM$1,$A3)*2 + MIN(DM$1,$A3) >= 227,1,0) -> 1 | DN3: =IF(MAX(DN$1,$A3)*2 + MIN(DN$1,$A3) >= 227,1,0) -> 1 | DO3: =IF(MAX(DO$1,$A3)*2 + MIN(DO$1,$A3) >= 227,1,0) -> 1 | DP3: =IF(MAX(DP$1,$A3)*2 + MIN(DP$1,$A3) >= 227,1,0) -> 1 | DQ3: =IF(MAX(DQ$1,$A3)*2 + MIN(DQ$1,$A3) >= 227,1,0) -> 1 | DR3: =IF(MAX(DR$1,$A3)*2 + MIN(DR$1,$A3) >= 227,1,0) -> 1 | DS3: =IF(MAX(DS$1,$A3)*2 + MIN(DS$1,$A3) >= 227,1,0) -> 1 | ... HS3: =IF(MAX(HS$1,$A3)*2 + MIN(HS$1,$A3) >= 227,1,0) -> 1
A4: 3 | B4: =IF(д!B4=0,IF(AND(INDEX($B$2:$HS$227,$A4+1,B$1)>0,INDEX($B$2:$HS$227,$A4,B$1+1)>0,INDEX($B$2:$HS$227,$A4*2,B$1)>0,INDEX($B$2:$HS$227,$A4,B$1*2)>0),-2,0) ,д!B4) -> 0 | C4: =IF(д!C4=0,IF(AND(INDEX($B$2:$HS$227,$A4+1,C$1)>0,INDEX($B$2:$HS$227,$A4,C$1+1)>0,INDEX($B$2:$HS$227,$A4*2,C$1)>0,INDEX($B$2:$HS$227,$A4,C$1*2)>0),-2,0) ,д!C4) -> 0 | D4: =IF(д!D4=0,IF(AND(INDEX($B$2:$HS$227,$A4+1,D$1)>0,INDEX($B$2:$HS$227,$A4,D$1+1)>0,INDEX($B$2:$HS$227,$A4*2,D$1)>0,INDEX($B$2:$HS$227,$A4,D$1*2)>0),-2,0) ,д!D4) -> 0 | E4: =IF(д!E4=0,IF(AND(INDEX($B$2:$HS$227,$A4+1,E$1)>0,INDEX($B$2:$HS$227,$A4,E$1+1)>0,INDEX($B$2:$HS$227,$A4*2,E$1)>0,INDEX($B$2:$HS$227,$A4,E$1*2)>0),-2,0) ,д!E4) -> 0 | F4: =IF(д!F4=0,IF(AND(INDEX($B$2:$HS$227,$A4+1,F$1)>0,INDEX($B$2:$HS$227,$A4,F$1+1)>0,INDEX($B$2:$HS$227,$A4*2,F$1)>0,INDEX($B$2:$HS$227,$A4,F$1*2)>0),-2,0) ,д!F4) -> 0 | G4: =IF(д!G4=0,IF(AND(INDEX($B$2:$HS$227,$A4+1,G$1)>0,INDEX($B$2:$HS$227,$A4,G$1+1)>0,INDEX($B$2:$HS$227,$A4*2,G$1)>0,INDEX($B$2:$HS$227,$A4,G$1*2)>0),-2,0) ,д!G4) -> 0 | H4: =IF(д!H4=0,IF(AND(INDEX($B$2:$HS$227,$A4+1,H$1)>0,INDEX($B$2:$HS$227,$A4,H$1+1)>0,INDEX($B$2:$HS$227,$A4*2,H$1)>0,INDEX($B$2:$HS$227,$A4,H$1*2)>0),-2,0) ,д!H4) -> 0 | I4: =IF(д!I4=0,IF(AND(INDEX($B$2:$HS$227,$A4+1,I$1)>0,INDEX($B$2:$HS$227,$A4,I$1+1)>0,INDEX($B$2:$HS$227,$A4*2,I$1)>0,INDEX($B$2:$HS$227,$A4,I$1*2)>0),-2,0) ,д!I4) -> 0 | ... DI4: =IF(д!DI4=0,IF(AND(INDEX($B$2:$HS$227,$A4+1,DI$1)>0,INDEX($B$2:$HS$227,$A4,DI$1+1)>0,INDEX($B$2:$HS$227,$A4*2,DI$1)>0,INDEX($B$2:$HS$227,$A4,DI$1*2)>0),-2,0) ,д!DI4) -> 1 | DJ4: =IF(д!DJ4=0,IF(OR(INDEX($B$2:$HS$227,$A4+1,DJ$1)<0,INDEX($B$2:$HS$227,$A4,DJ$1+1)<0,INDEX($B$2:$HS$227,$A4*2,DJ$1)<0,INDEX($B$2:$HS$227,$A4,DJ$1*2)<0),2,0) ,д!DJ4) -> 1 | DK4: =IF(д!DK4=0,IF(OR(INDEX($B$2:$HS$227,$A4+1,DK$1)>0,INDEX($B$2:$HS$227,$A4,DK$1+1)>0,INDEX($B$2:$HS$227,$A4*2,DK$1)>0,INDEX($B$2:$HS$227,$A4,DK$1*2)>0),-1,0) ,д!DK4) -> 1 | DL4: =IF(MAX(DL$1,$A4)*2 + MIN(DL$1,$A4) >= 227,1,0) -> 1 | DM4: =IF(MAX(DM$1,$A4)*2 + MIN(DM$1,$A4) >= 227,1,0) -> 1 | DN4: =IF(MAX(DN$1,$A4)*2 + MIN(DN$1,$A4) >= 227,1,0) -> 1 | DO4: =IF(MAX(DO$1,$A4)*2 + MIN(DO$1,$A4) >= 227,1,0) -> 1 | DP4: =IF(MAX(DP$1,$A4)*2 + MIN(DP$1,$A4) >= 227,1,0) -> 1 | DQ4: =IF(MAX(DQ$1,$A4)*2 + MIN(DQ$1,$A4) >= 227,1,0) -> 1 | DR4: =IF(MAX(DR$1,$A4)*2 + MIN(DR$1,$A4) >= 227,1,0) -> 1 | DS4: =IF(MAX(DS$1,$A4)*2 + MIN(DS$1,$A4) >= 227,1,0) -> 1 | ... HS4: =IF(MAX(HS$1,$A4)*2 + MIN(HS$1,$A4) >= 227,1,0) -> 1
A5: 4 | B5: =IF(д!B5=0,IF(AND(INDEX($B$2:$HS$227,$A5+1,B$1)>0,INDEX($B$2:$HS$227,$A5,B$1+1)>0,INDEX($B$2:$HS$227,$A5*2,B$1)>0,INDEX($B$2:$HS$227,$A5,B$1*2)>0),-2,0) ,д!B5) -> 0 | C5: =IF(д!C5=0,IF(AND(INDEX($B$2:$HS$227,$A5+1,C$1)>0,INDEX($B$2:$HS$227,$A5,C$1+1)>0,INDEX($B$2:$HS$227,$A5*2,C$1)>0,INDEX($B$2:$HS$227,$A5,C$1*2)>0),-2,0) ,д!C5) -> 0 | D5: =IF(д!D5=0,IF(AND(INDEX($B$2:$HS$227,$A5+1,D$1)>0,INDEX($B$2:$HS$227,$A5,D$1+1)>0,INDEX($B$2:$HS$227,$A5*2,D$1)>0,INDEX($B$2:$HS$227,$A5,D$1*2)>0),-2,0) ,д!D5) -> 0 | E5: =IF(д!E5=0,IF(AND(INDEX($B$2:$HS$227,$A5+1,E$1)>0,INDEX($B$2:$HS$227,$A5,E$1+1)>0,INDEX($B$2:$HS$227,$A5*2,E$1)>0,INDEX($B$2:$HS$227,$A5,E$1*2)>0),-2,0) ,д!E5) -> 0 | F5: =IF(д!F5=0,IF(AND(INDEX($B$2:$HS$227,$A5+1,F$1)>0,INDEX($B$2:$HS$227,$A5,F$1+1)>0,INDEX($B$2:$HS$227,$A5*2,F$1)>0,INDEX($B$2:$HS$227,$A5,F$1*2)>0),-2,0) ,д!F5) -> 0 | G5: =IF(д!G5=0,IF(AND(INDEX($B$2:$HS$227,$A5+1,G$1)>0,INDEX($B$2:$HS$227,$A5,G$1+1)>0,INDEX($B$2:$HS$227,$A5*2,G$1)>0,INDEX($B$2:$HS$227,$A5,G$1*2)>0),-2,0) ,д!G5) -> 0 | H5: =IF(д!H5=0,IF(AND(INDEX($B$2:$HS$227,$A5+1,H$1)>0,INDEX($B$2:$HS$227,$A5,H$1+1)>0,INDEX($B$2:$HS$227,$A5*2,H$1)>0,INDEX($B$2:$HS$227,$A5,H$1*2)>0),-2,0) ,д!H5) -> 0 | I5: =IF(д!I5=0,IF(AND(INDEX($B$2:$HS$227,$A5+1,I$1)>0,INDEX($B$2:$HS$227,$A5,I$1+1)>0,INDEX($B$2:$HS$227,$A5*2,I$1)>0,INDEX($B$2:$HS$227,$A5,I$1*2)>0),-2,0) ,д!I5) -> 0 | ... DI5: =IF(д!DI5=0,IF(AND(INDEX($B$2:$HS$227,$A5+1,DI$1)>0,INDEX($B$2:$HS$227,$A5,DI$1+1)>0,INDEX($B$2:$HS$227,$A5*2,DI$1)>0,INDEX($B$2:$HS$227,$A5,DI$1*2)>0),-2,0) ,д!DI5) -> 1 | DJ5: =IF(д!DJ5=0,IF(OR(INDEX($B$2:$HS$227,$A5+1,DJ$1)<0,INDEX($B$2:$HS$227,$A5,DJ$1+1)<0,INDEX($B$2:$HS$227,$A5*2,DJ$1)<0,INDEX($B$2:$HS$227,$A5,DJ$1*2)<0),2,0) ,д!DJ5) -> 1 | DK5: =IF(д!DK5=0,IF(OR(INDEX($B$2:$HS$227,$A5+1,DK$1)>0,INDEX($B$2:$HS$227,$A5,DK$1+1)>0,INDEX($B$2:$HS$227,$A5*2,DK$1)>0,INDEX($B$2:$HS$227,$A5,DK$1*2)>0),-1,0) ,д!DK5) -> 1 | DL5: =IF(MAX(DL$1,$A5)*2 + MIN(DL$1,$A5) >= 227,1,0) -> 1 | DM5: =IF(MAX(DM$1,$A5)*2 + MIN(DM$1,$A5) >= 227,1,0) -> 1 | DN5: =IF(MAX(DN$1,$A5)*2 + MIN(DN$1,$A5) >= 227,1,0) -> 1 | DO5: =IF(MAX(DO$1,$A5)*2 + MIN(DO$1,$A5) >= 227,1,0) -> 1 | DP5: =IF(MAX(DP$1,$A5)*2 + MIN(DP$1,$A5) >= 227,1,0) -> 1 | DQ5: =IF(MAX(DQ$1,$A5)*2 + MIN(DQ$1,$A5) >= 227,1,0) -> 1 | DR5: =IF(MAX(DR$1,$A5)*2 + MIN(DR$1,$A5) >= 227,1,0) -> 1 | DS5: =IF(MAX(DS$1,$A5)*2 + MIN(DS$1,$A5) >= 227,1,0) -> 1 | ... HS5: =IF(MAX(HS$1,$A5)*2 + MIN(HS$1,$A5) >= 227,1,0) -> 1
A6: 5 | B6: =IF(д!B6=0,IF(AND(INDEX($B$2:$HS$227,$A6+1,B$1)>0,INDEX($B$2:$HS$227,$A6,B$1+1)>0,INDEX($B$2:$HS$227,$A6*2,B$1)>0,INDEX($B$2:$HS$227,$A6,B$1*2)>0),-2,0) ,д!B6) -> 0 | C6: =IF(д!C6=0,IF(AND(INDEX($B$2:$HS$227,$A6+1,C$1)>0,INDEX($B$2:$HS$227,$A6,C$1+1)>0,INDEX($B$2:$HS$227,$A6*2,C$1)>0,INDEX($B$2:$HS$227,$A6,C$1*2)>0),-2,0) ,д!C6) -> 0 | D6: =IF(д!D6=0,IF(AND(INDEX($B$2:$HS$227,$A6+1,D$1)>0,INDEX($B$2:$HS$227,$A6,D$1+1)>0,INDEX($B$2:$HS$227,$A6*2,D$1)>0,INDEX($B$2:$HS$227,$A6,D$1*2)>0),-2,0) ,д!D6) -> 0 | E6: =IF(д!E6=0,IF(AND(INDEX($B$2:$HS$227,$A6+1,E$1)>0,INDEX($B$2:$HS$227,$A6,E$1+1)>0,INDEX($B$2:$HS$227,$A6*2,E$1)>0,INDEX($B$2:$HS$227,$A6,E$1*2)>0),-2,0) ,д!E6) -> 0 | F6: =IF(д!F6=0,IF(AND(INDEX($B$2:$HS$227,$A6+1,F$1)>0,INDEX($B$2:$HS$227,$A6,F$1+1)>0,INDEX($B$2:$HS$227,$A6*2,F$1)>0,INDEX($B$2:$HS$227,$A6,F$1*2)>0),-2,0) ,д!F6) -> 0 | G6: =IF(д!G6=0,IF(AND(INDEX($B$2:$HS$227,$A6+1,G$1)>0,INDEX($B$2:$HS$227,$A6,G$1+1)>0,INDEX($B$2:$HS$227,$A6*2,G$1)>0,INDEX($B$2:$HS$227,$A6,G$1*2)>0),-2,0) ,д!G6) -> 0 | H6: =IF(д!H6=0,IF(AND(INDEX($B$2:$HS$227,$A6+1,H$1)>0,INDEX($B$2:$HS$227,$A6,H$1+1)>0,INDEX($B$2:$HS$227,$A6*2,H$1)>0,INDEX($B$2:$HS$227,$A6,H$1*2)>0),-2,0) ,д!H6) -> 0 | I6: =IF(д!I6=0,IF(AND(INDEX($B$2:$HS$227,$A6+1,I$1)>0,INDEX($B$2:$HS$227,$A6,I$1+1)>0,INDEX($B$2:$HS$227,$A6*2,I$1)>0,INDEX($B$2:$HS$227,$A6,I$1*2)>0),-2,0) ,д!I6) -> 0 | ... DI6: =IF(д!DI6=0,IF(AND(INDEX($B$2:$HS$227,$A6+1,DI$1)>0,INDEX($B$2:$HS$227,$A6,DI$1+1)>0,INDEX($B$2:$HS$227,$A6*2,DI$1)>0,INDEX($B$2:$HS$227,$A6,DI$1*2)>0),-2,0) ,д!DI6) -> 1 | DJ6: =IF(д!DJ6=0,IF(OR(INDEX($B$2:$HS$227,$A6+1,DJ$1)<0,INDEX($B$2:$HS$227,$A6,DJ$1+1)<0,INDEX($B$2:$HS$227,$A6*2,DJ$1)<0,INDEX($B$2:$HS$227,$A6,DJ$1*2)<0),2,0) ,д!DJ6) -> 1 | DK6: =IF(д!DK6=0,IF(OR(INDEX($B$2:$HS$227,$A6+1,DK$1)>0,INDEX($B$2:$HS$227,$A6,DK$1+1)>0,INDEX($B$2:$HS$227,$A6*2,DK$1)>0,INDEX($B$2:$HS$227,$A6,DK$1*2)>0),-1,0) ,д!DK6) -> 1 | DL6: =IF(MAX(DL$1,$A6)*2 + MIN(DL$1,$A6) >= 227,1,0) -> 1 | DM6: =IF(MAX(DM$1,$A6)*2 + MIN(DM$1,$A6) >= 227,1,0) -> 1 | DN6: =IF(MAX(DN$1,$A6)*2 + MIN(DN$1,$A6) >= 227,1,0) -> 1 | DO6: =IF(MAX(DO$1,$A6)*2 + MIN(DO$1,$A6) >= 227,1,0) -> 1 | DP6: =IF(MAX(DP$1,$A6)*2 + MIN(DP$1,$A6) >= 227,1,0) -> 1 | DQ6: =IF(MAX(DQ$1,$A6)*2 + MIN(DQ$1,$A6) >= 227,1,0) -> 1 | DR6: =IF(MAX(DR$1,$A6)*2 + MIN(DR$1,$A6) >= 227,1,0) -> 1 | DS6: =IF(MAX(DS$1,$A6)*2 + MIN(DS$1,$A6) >= 227,1,0) -> 1 | ... HS6: =IF(MAX(HS$1,$A6)*2 + MIN(HS$1,$A6) >= 227,1,0) -> 1
A7: 6 | B7: =IF(д!B7=0,IF(AND(INDEX($B$2:$HS$227,$A7+1,B$1)>0,INDEX($B$2:$HS$227,$A7,B$1+1)>0,INDEX($B$2:$HS$227,$A7*2,B$1)>0,INDEX($B$2:$HS$227,$A7,B$1*2)>0),-2,0) ,д!B7) -> 0 | C7: =IF(д!C7=0,IF(AND(INDEX($B$2:$HS$227,$A7+1,C$1)>0,INDEX($B$2:$HS$227,$A7,C$1+1)>0,INDEX($B$2:$HS$227,$A7*2,C$1)>0,INDEX($B$2:$HS$227,$A7,C$1*2)>0),-2,0) ,д!C7) -> 0 | D7: =IF(д!D7=0,IF(AND(INDEX($B$2:$HS$227,$A7+1,D$1)>0,INDEX($B$2:$HS$227,$A7,D$1+1)>0,INDEX($B$2:$HS$227,$A7*2,D$1)>0,INDEX($B$2:$HS$227,$A7,D$1*2)>0),-2,0) ,д!D7) -> 0 | E7: =IF(д!E7=0,IF(AND(INDEX($B$2:$HS$227,$A7+1,E$1)>0,INDEX($B$2:$HS$227,$A7,E$1+1)>0,INDEX($B$2:$HS$227,$A7*2,E$1)>0,INDEX($B$2:$HS$227,$A7,E$1*2)>0),-2,0) ,д!E7) -> 0 | F7: =IF(д!F7=0,IF(AND(INDEX($B$2:$HS$227,$A7+1,F$1)>0,INDEX($B$2:$HS$227,$A7,F$1+1)>0,INDEX($B$2:$HS$227,$A7*2,F$1)>0,INDEX($B$2:$HS$227,$A7,F$1*2)>0),-2,0) ,д!F7) -> 0 | G7: =IF(д!G7=0,IF(AND(INDEX($B$2:$HS$227,$A7+1,G$1)>0,INDEX($B$2:$HS$227,$A7,G$1+1)>0,INDEX($B$2:$HS$227,$A7*2,G$1)>0,INDEX($B$2:$HS$227,$A7,G$1*2)>0),-2,0) ,д!G7) -> 0 | H7: =IF(д!H7=0,IF(AND(INDEX($B$2:$HS$227,$A7+1,H$1)>0,INDEX($B$2:$HS$227,$A7,H$1+1)>0,INDEX($B$2:$HS$227,$A7*2,H$1)>0,INDEX($B$2:$HS$227,$A7,H$1*2)>0),-2,0) ,д!H7) -> 0 | I7: =IF(д!I7=0,IF(AND(INDEX($B$2:$HS$227,$A7+1,I$1)>0,INDEX($B$2:$HS$227,$A7,I$1+1)>0,INDEX($B$2:$HS$227,$A7*2,I$1)>0,INDEX($B$2:$HS$227,$A7,I$1*2)>0),-2,0) ,д!I7) -> 0 | ... DI7: =IF(д!DI7=0,IF(AND(INDEX($B$2:$HS$227,$A7+1,DI$1)>0,INDEX($B$2:$HS$227,$A7,DI$1+1)>0,INDEX($B$2:$HS$227,$A7*2,DI$1)>0,INDEX($B$2:$HS$227,$A7,DI$1*2)>0),-2,0) ,д!DI7) -> 1 | DJ7: =IF(д!DJ7=0,IF(OR(INDEX($B$2:$HS$227,$A7+1,DJ$1)<0,INDEX($B$2:$HS$227,$A7,DJ$1+1)<0,INDEX($B$2:$HS$227,$A7*2,DJ$1)<0,INDEX($B$2:$HS$227,$A7,DJ$1*2)<0),2,0) ,д!DJ7) -> 1 | DK7: =IF(д!DK7=0,IF(OR(INDEX($B$2:$HS$227,$A7+1,DK$1)>0,INDEX($B$2:$HS$227,$A7,DK$1+1)>0,INDEX($B$2:$HS$227,$A7*2,DK$1)>0,INDEX($B$2:$HS$227,$A7,DK$1*2)>0),-1,0) ,д!DK7) -> 1 | DL7: =IF(MAX(DL$1,$A7)*2 + MIN(DL$1,$A7) >= 227,1,0) -> 1 | DM7: =IF(MAX(DM$1,$A7)*2 + MIN(DM$1,$A7) >= 227,1,0) -> 1 | DN7: =IF(MAX(DN$1,$A7)*2 + MIN(DN$1,$A7) >= 227,1,0) -> 1 | DO7: =IF(MAX(DO$1,$A7)*2 + MIN(DO$1,$A7) >= 227,1,0) -> 1 | DP7: =IF(MAX(DP$1,$A7)*2 + MIN(DP$1,$A7) >= 227,1,0) -> 1 | DQ7: =IF(MAX(DQ$1,$A7)*2 + MIN(DQ$1,$A7) >= 227,1,0) -> 1 | DR7: =IF(MAX(DR$1,$A7)*2 + MIN(DR$1,$A7) >= 227,1,0) -> 1 | DS7: =IF(MAX(DS$1,$A7)*2 + MIN(DS$1,$A7) >= 227,1,0) -> 1 | ... HS7: =IF(MAX(HS$1,$A7)*2 + MIN(HS$1,$A7) >= 227,1,0) -> 1
A8: 7 | B8: =IF(д!B8=0,IF(AND(INDEX($B$2:$HS$227,$A8+1,B$1)>0,INDEX($B$2:$HS$227,$A8,B$1+1)>0,INDEX($B$2:$HS$227,$A8*2,B$1)>0,INDEX($B$2:$HS$227,$A8,B$1*2)>0),-2,0) ,д!B8) -> 0 | C8: =IF(д!C8=0,IF(AND(INDEX($B$2:$HS$227,$A8+1,C$1)>0,INDEX($B$2:$HS$227,$A8,C$1+1)>0,INDEX($B$2:$HS$227,$A8*2,C$1)>0,INDEX($B$2:$HS$227,$A8,C$1*2)>0),-2,0) ,д!C8) -> 0 | D8: =IF(д!D8=0,IF(AND(INDEX($B$2:$HS$227,$A8+1,D$1)>0,INDEX($B$2:$HS$227,$A8,D$1+1)>0,INDEX($B$2:$HS$227,$A8*2,D$1)>0,INDEX($B$2:$HS$227,$A8,D$1*2)>0),-2,0) ,д!D8) -> 0 | E8: =IF(д!E8=0,IF(AND(INDEX($B$2:$HS$227,$A8+1,E$1)>0,INDEX($B$2:$HS$227,$A8,E$1+1)>0,INDEX($B$2:$HS$227,$A8*2,E$1)>0,INDEX($B$2:$HS$227,$A8,E$1*2)>0),-2,0) ,д!E8) -> 0 | F8: =IF(д!F8=0,IF(AND(INDEX($B$2:$HS$227,$A8+1,F$1)>0,INDEX($B$2:$HS$227,$A8,F$1+1)>0,INDEX($B$2:$HS$227,$A8*2,F$1)>0,INDEX($B$2:$HS$227,$A8,F$1*2)>0),-2,0) ,д!F8) -> 0 | G8: =IF(д!G8=0,IF(AND(INDEX($B$2:$HS$227,$A8+1,G$1)>0,INDEX($B$2:$HS$227,$A8,G$1+1)>0,INDEX($B$2:$HS$227,$A8*2,G$1)>0,INDEX($B$2:$HS$227,$A8,G$1*2)>0),-2,0) ,д!G8) -> 0 | H8: =IF(д!H8=0,IF(AND(INDEX($B$2:$HS$227,$A8+1,H$1)>0,INDEX($B$2:$HS$227,$A8,H$1+1)>0,INDEX($B$2:$HS$227,$A8*2,H$1)>0,INDEX($B$2:$HS$227,$A8,H$1*2)>0),-2,0) ,д!H8) -> 0 | I8: =IF(д!I8=0,IF(AND(INDEX($B$2:$HS$227,$A8+1,I$1)>0,INDEX($B$2:$HS$227,$A8,I$1+1)>0,INDEX($B$2:$HS$227,$A8*2,I$1)>0,INDEX($B$2:$HS$227,$A8,I$1*2)>0),-2,0) ,д!I8) -> 0 | ... DI8: =IF(д!DI8=0,IF(AND(INDEX($B$2:$HS$227,$A8+1,DI$1)>0,INDEX($B$2:$HS$227,$A8,DI$1+1)>0,INDEX($B$2:$HS$227,$A8*2,DI$1)>0,INDEX($B$2:$HS$227,$A8,DI$1*2)>0),-2,0) ,д!DI8) -> 1 | DJ8: =IF(д!DJ8=0,IF(OR(INDEX($B$2:$HS$227,$A8+1,DJ$1)<0,INDEX($B$2:$HS$227,$A8,DJ$1+1)<0,INDEX($B$2:$HS$227,$A8*2,DJ$1)<0,INDEX($B$2:$HS$227,$A8,DJ$1*2)<0),2,0) ,д!DJ8) -> 1 | DK8: =IF(д!DK8=0,IF(OR(INDEX($B$2:$HS$227,$A8+1,DK$1)>0,INDEX($B$2:$HS$227,$A8,DK$1+1)>0,INDEX($B$2:$HS$227,$A8*2,DK$1)>0,INDEX($B$2:$HS$227,$A8,DK$1*2)>0),-1,0) ,д!DK8) -> 1 | DL8: =IF(MAX(DL$1,$A8)*2 + MIN(DL$1,$A8) >= 227,1,0) -> 1 | DM8: =IF(MAX(DM$1,$A8)*2 + MIN(DM$1,$A8) >= 227,1,0) -> 1 | DN8: =IF(MAX(DN$1,$A8)*2 + MIN(DN$1,$A8) >= 227,1,0) -> 1 | DO8: =IF(MAX(DO$1,$A8)*2 + MIN(DO$1,$A8) >= 227,1,0) -> 1 | DP8: =IF(MAX(DP$1,$A8)*2 + MIN(DP$1,$A8) >= 227,1,0) -> 1 | DQ8: =IF(MAX(DQ$1,$A8)*2 + MIN(DQ$1,$A8) >= 227,1,0) -> 1 | DR8: =IF(MAX(DR$1,$A8)*2 + MIN(DR$1,$A8) >= 227,1,0) -> 1 | DS8: =IF(MAX(DS$1,$A8)*2 + MIN(DS$1,$A8) >= 227,1,0) -> 1 | ... HS8: =IF(MAX(HS$1,$A8)*2 + MIN(HS$1,$A8) >= 227,1,0) -> 1
A9: 8 | B9: =IF(д!B9=0,IF(AND(INDEX($B$2:$HS$227,$A9+1,B$1)>0,INDEX($B$2:$HS$227,$A9,B$1+1)>0,INDEX($B$2:$HS$227,$A9*2,B$1)>0,INDEX($B$2:$HS$227,$A9,B$1*2)>0),-2,0) ,д!B9) -> 0 | C9: =IF(д!C9=0,IF(AND(INDEX($B$2:$HS$227,$A9+1,C$1)>0,INDEX($B$2:$HS$227,$A9,C$1+1)>0,INDEX($B$2:$HS$227,$A9*2,C$1)>0,INDEX($B$2:$HS$227,$A9,C$1*2)>0),-2,0) ,д!C9) -> 0 | D9: =IF(д!D9=0,IF(AND(INDEX($B$2:$HS$227,$A9+1,D$1)>0,INDEX($B$2:$HS$227,$A9,D$1+1)>0,INDEX($B$2:$HS$227,$A9*2,D$1)>0,INDEX($B$2:$HS$227,$A9,D$1*2)>0),-2,0) ,д!D9) -> 0 | E9: =IF(д!E9=0,IF(AND(INDEX($B$2:$HS$227,$A9+1,E$1)>0,INDEX($B$2:$HS$227,$A9,E$1+1)>0,INDEX($B$2:$HS$227,$A9*2,E$1)>0,INDEX($B$2:$HS$227,$A9,E$1*2)>0),-2,0) ,д!E9) -> 0 | F9: =IF(д!F9=0,IF(AND(INDEX($B$2:$HS$227,$A9+1,F$1)>0,INDEX($B$2:$HS$227,$A9,F$1+1)>0,INDEX($B$2:$HS$227,$A9*2,F$1)>0,INDEX($B$2:$HS$227,$A9,F$1*2)>0),-2,0) ,д!F9) -> 0 | G9: =IF(д!G9=0,IF(AND(INDEX($B$2:$HS$227,$A9+1,G$1)>0,INDEX($B$2:$HS$227,$A9,G$1+1)>0,INDEX($B$2:$HS$227,$A9*2,G$1)>0,INDEX($B$2:$HS$227,$A9,G$1*2)>0),-2,0) ,д!G9) -> 0 | H9: =IF(д!H9=0,IF(AND(INDEX($B$2:$HS$227,$A9+1,H$1)>0,INDEX($B$2:$HS$227,$A9,H$1+1)>0,INDEX($B$2:$HS$227,$A9*2,H$1)>0,INDEX($B$2:$HS$227,$A9,H$1*2)>0),-2,0) ,д!H9) -> 0 | I9: =IF(д!I9=0,IF(AND(INDEX($B$2:$HS$227,$A9+1,I$1)>0,INDEX($B$2:$HS$227,$A9,I$1+1)>0,INDEX($B$2:$HS$227,$A9*2,I$1)>0,INDEX($B$2:$HS$227,$A9,I$1*2)>0),-2,0) ,д!I9) -> 0 | ... DI9: =IF(д!DI9=0,IF(AND(INDEX($B$2:$HS$227,$A9+1,DI$1)>0,INDEX($B$2:$HS$227,$A9,DI$1+1)>0,INDEX($B$2:$HS$227,$A9*2,DI$1)>0,INDEX($B$2:$HS$227,$A9,DI$1*2)>0),-2,0) ,д!DI9) -> 1 | DJ9: =IF(д!DJ9=0,IF(OR(INDEX($B$2:$HS$227,$A9+1,DJ$1)<0,INDEX($B$2:$HS$227,$A9,DJ$1+1)<0,INDEX($B$2:$HS$227,$A9*2,DJ$1)<0,INDEX($B$2:$HS$227,$A9,DJ$1*2)<0),2,0) ,д!DJ9) -> 1 | DK9: =IF(д!DK9=0,IF(OR(INDEX($B$2:$HS$227,$A9+1,DK$1)>0,INDEX($B$2:$HS$227,$A9,DK$1+1)>0,INDEX($B$2:$HS$227,$A9*2,DK$1)>0,INDEX($B$2:$HS$227,$A9,DK$1*2)>0),-1,0) ,д!DK9) -> 1 | DL9: =IF(MAX(DL$1,$A9)*2 + MIN(DL$1,$A9) >= 227,1,0) -> 1 | DM9: =IF(MAX(DM$1,$A9)*2 + MIN(DM$1,$A9) >= 227,1,0) -> 1 | DN9: =IF(MAX(DN$1,$A9)*2 + MIN(DN$1,$A9) >= 227,1,0) -> 1 | DO9: =IF(MAX(DO$1,$A9)*2 + MIN(DO$1,$A9) >= 227,1,0) -> 1 | DP9: =IF(MAX(DP$1,$A9)*2 + MIN(DP$1,$A9) >= 227,1,0) -> 1 | DQ9: =IF(MAX(DQ$1,$A9)*2 + MIN(DQ$1,$A9) >= 227,1,0) -> 1 | DR9: =IF(MAX(DR$1,$A9)*2 + MIN(DR$1,$A9) >= 227,1,0) -> 1 | DS9: =IF(MAX(DS$1,$A9)*2 + MIN(DS$1,$A9) >= 227,1,0) -> 1 | ... HS9: =IF(MAX(HS$1,$A9)*2 + MIN(HS$1,$A9) >= 227,1,0) -> 1
A10: 9 | B10: =IF(д!B10=0,IF(AND(INDEX($B$2:$HS$227,$A10+1,B$1)>0,INDEX($B$2:$HS$227,$A10,B$1+1)>0,INDEX($B$2:$HS$227,$A10*2,B$1)>0,INDEX($B$2:$HS$227,$A10,B$1*2)>0),-2,0) ,д!B10) -> 0 | C10: =IF(д!C10=0,IF(AND(INDEX($B$2:$HS$227,$A10+1,C$1)>0,INDEX($B$2:$HS$227,$A10,C$1+1)>0,INDEX($B$2:$HS$227,$A10*2,C$1)>0,INDEX($B$2:$HS$227,$A10,C$1*2)>0),-2,0) ,д!C10) -> 0 | D10: =IF(д!D10=0,IF(AND(INDEX($B$2:$HS$227,$A10+1,D$1)>0,INDEX($B$2:$HS$227,$A10,D$1+1)>0,INDEX($B$2:$HS$227,$A10*2,D$1)>0,INDEX($B$2:$HS$227,$A10,D$1*2)>0),-2,0) ,д!D10) -> 0 | E10: =IF(д!E10=0,IF(AND(INDEX($B$2:$HS$227,$A10+1,E$1)>0,INDEX($B$2:$HS$227,$A10,E$1+1)>0,INDEX($B$2:$HS$227,$A10*2,E$1)>0,INDEX($B$2:$HS$227,$A10,E$1*2)>0),-2,0) ,д!E10) -> 0 | F10: =IF(д!F10=0,IF(AND(INDEX($B$2:$HS$227,$A10+1,F$1)>0,INDEX($B$2:$HS$227,$A10,F$1+1)>0,INDEX($B$2:$HS$227,$A10*2,F$1)>0,INDEX($B$2:$HS$227,$A10,F$1*2)>0),-2,0) ,д!F10) -> 0 | G10: =IF(д!G10=0,IF(AND(INDEX($B$2:$HS$227,$A10+1,G$1)>0,INDEX($B$2:$HS$227,$A10,G$1+1)>0,INDEX($B$2:$HS$227,$A10*2,G$1)>0,INDEX($B$2:$HS$227,$A10,G$1*2)>0),-2,0) ,д!G10) -> 0 | H10: =IF(д!H10=0,IF(AND(INDEX($B$2:$HS$227,$A10+1,H$1)>0,INDEX($B$2:$HS$227,$A10,H$1+1)>0,INDEX($B$2:$HS$227,$A10*2,H$1)>0,INDEX($B$2:$HS$227,$A10,H$1*2)>0),-2,0) ,д!H10) -> 0 | I10: =IF(д!I10=0,IF(AND(INDEX($B$2:$HS$227,$A10+1,I$1)>0,INDEX($B$2:$HS$227,$A10,I$1+1)>0,INDEX($B$2:$HS$227,$A10*2,I$1)>0,INDEX($B$2:$HS$227,$A10,I$1*2)>0),-2,0) ,д!I10) -> 0 | ... DI10: =IF(д!DI10=0,IF(AND(INDEX($B$2:$HS$227,$A10+1,DI$1)>0,INDEX($B$2:$HS$227,$A10,DI$1+1)>0,INDEX($B$2:$HS$227,$A10*2,DI$1)>0,INDEX($B$2:$HS$227,$A10,DI$1*2)>0),-2,0) ,д!DI10) -> 1 | DJ10: =IF(д!DJ10=0,IF(OR(INDEX($B$2:$HS$227,$A10+1,DJ$1)<0,INDEX($B$2:$HS$227,$A10,DJ$1+1)<0,INDEX($B$2:$HS$227,$A10*2,DJ$1)<0,INDEX($B$2:$HS$227,$A10,DJ$1*2)<0),2,0) ,д!DJ10) -> 1 | DK10: =IF(д!DK10=0,IF(OR(INDEX($B$2:$HS$227,$A10+1,DK$1)>0,INDEX($B$2:$HS$227,$A10,DK$1+1)>0,INDEX($B$2:$HS$227,$A10*2,DK$1)>0,INDEX($B$2:$HS$227,$A10,DK$1*2)>0),-1,0) ,д!DK10) -> 1 | DL10: =IF(MAX(DL$1,$A10)*2 + MIN(DL$1,$A10) >= 227,1,0) -> 1 | DM10: =IF(MAX(DM$1,$A10)*2 + MIN(DM$1,$A10) >= 227,1,0) -> 1 | DN10: =IF(MAX(DN$1,$A10)*2 + MIN(DN$1,$A10) >= 227,1,0) -> 1 | DO10: =IF(MAX(DO$1,$A10)*2 + MIN(DO$1,$A10) >= 227,1,0) -> 1 | DP10: =IF(MAX(DP$1,$A10)*2 + MIN(DP$1,$A10) >= 227,1,0) -> 1 | DQ10: =IF(MAX(DQ$1,$A10)*2 + MIN(DQ$1,$A10) >= 227,1,0) -> 1 | DR10: =IF(MAX(DR$1,$A10)*2 + MIN(DR$1,$A10) >= 227,1,0) -> 1 | DS10: =IF(MAX(DS$1,$A10)*2 + MIN(DS$1,$A10) >= 227,1,0) -> 1 | ... HS10: =IF(MAX(HS$1,$A10)*2 + MIN(HS$1,$A10) >= 227,1,0) -> 1
A11: 10 | B11: =IF(д!B11=0,IF(AND(INDEX($B$2:$HS$227,$A11+1,B$1)>0,INDEX($B$2:$HS$227,$A11,B$1+1)>0,INDEX($B$2:$HS$227,$A11*2,B$1)>0,INDEX($B$2:$HS$227,$A11,B$1*2)>0),-2,0) ,д!B11) -> 0 | C11: =IF(д!C11=0,IF(AND(INDEX($B$2:$HS$227,$A11+1,C$1)>0,INDEX($B$2:$HS$227,$A11,C$1+1)>0,INDEX($B$2:$HS$227,$A11*2,C$1)>0,INDEX($B$2:$HS$227,$A11,C$1*2)>0),-2,0) ,д!C11) -> 0 | D11: =IF(д!D11=0,IF(AND(INDEX($B$2:$HS$227,$A11+1,D$1)>0,INDEX($B$2:$HS$227,$A11,D$1+1)>0,INDEX($B$2:$HS$227,$A11*2,D$1)>0,INDEX($B$2:$HS$227,$A11,D$1*2)>0),-2,0) ,д!D11) -> 0 | E11: =IF(д!E11=0,IF(AND(INDEX($B$2:$HS$227,$A11+1,E$1)>0,INDEX($B$2:$HS$227,$A11,E$1+1)>0,INDEX($B$2:$HS$227,$A11*2,E$1)>0,INDEX($B$2:$HS$227,$A11,E$1*2)>0),-2,0) ,д!E11) -> 0 | F11: =IF(д!F11=0,IF(AND(INDEX($B$2:$HS$227,$A11+1,F$1)>0,INDEX($B$2:$HS$227,$A11,F$1+1)>0,INDEX($B$2:$HS$227,$A11*2,F$1)>0,INDEX($B$2:$HS$227,$A11,F$1*2)>0),-2,0) ,д!F11) -> 0 | G11: =IF(д!G11=0,IF(AND(INDEX($B$2:$HS$227,$A11+1,G$1)>0,INDEX($B$2:$HS$227,$A11,G$1+1)>0,INDEX($B$2:$HS$227,$A11*2,G$1)>0,INDEX($B$2:$HS$227,$A11,G$1*2)>0),-2,0) ,д!G11) -> 0 | H11: =IF(д!H11=0,IF(AND(INDEX($B$2:$HS$227,$A11+1,H$1)>0,INDEX($B$2:$HS$227,$A11,H$1+1)>0,INDEX($B$2:$HS$227,$A11*2,H$1)>0,INDEX($B$2:$HS$227,$A11,H$1*2)>0),-2,0) ,д!H11) -> 0 | I11: =IF(д!I11=0,IF(AND(INDEX($B$2:$HS$227,$A11+1,I$1)>0,INDEX($B$2:$HS$227,$A11,I$1+1)>0,INDEX($B$2:$HS$227,$A11*2,I$1)>0,INDEX($B$2:$HS$227,$A11,I$1*2)>0),-2,0) ,д!I11) -> 0 | ... DI11: =IF(д!DI11=0,IF(AND(INDEX($B$2:$HS$227,$A11+1,DI$1)>0,INDEX($B$2:$HS$227,$A11,DI$1+1)>0,INDEX($B$2:$HS$227,$A11*2,DI$1)>0,INDEX($B$2:$HS$227,$A11,DI$1*2)>0),-2,0) ,д!DI11) -> 1 | DJ11: =IF(д!DJ11=0,IF(OR(INDEX($B$2:$HS$227,$A11+1,DJ$1)<0,INDEX($B$2:$HS$227,$A11,DJ$1+1)<0,INDEX($B$2:$HS$227,$A11*2,DJ$1)<0,INDEX($B$2:$HS$227,$A11,DJ$1*2)<0),2,0) ,д!DJ11) -> 1 | DK11: =IF(д!DK11=0,IF(OR(INDEX($B$2:$HS$227,$A11+1,DK$1)>0,INDEX($B$2:$HS$227,$A11,DK$1+1)>0,INDEX($B$2:$HS$227,$A11*2,DK$1)>0,INDEX($B$2:$HS$227,$A11,DK$1*2)>0),-1,0) ,д!DK11) -> 1 | DL11: =IF(MAX(DL$1,$A11)*2 + MIN(DL$1,$A11) >= 227,1,0) -> 1 | DM11: =IF(MAX(DM$1,$A11)*2 + MIN(DM$1,$A11) >= 227,1,0) -> 1 | DN11: =IF(MAX(DN$1,$A11)*2 + MIN(DN$1,$A11) >= 227,1,0) -> 1 | DO11: =IF(MAX(DO$1,$A11)*2 + MIN(DO$1,$A11) >= 227,1,0) -> 1 | DP11: =IF(MAX(DP$1,$A11)*2 + MIN(DP$1,$A11) >= 227,1,0) -> 1 | DQ11: =IF(MAX(DQ$1,$A11)*2 + MIN(DQ$1,$A11) >= 227,1,0) -> 1 | DR11: =IF(MAX(DR$1,$A11)*2 + MIN(DR$1,$A11) >= 227,1,0) -> 1 | DS11: =IF(MAX(DS$1,$A11)*2 + MIN(DS$1,$A11) >= 227,1,0) -> 1 | ... HS11: =IF(MAX(HS$1,$A11)*2 + MIN(HS$1,$A11) >= 227,1,0) -> 1
A12: 11 | B12: =IF(д!B12=0,IF(AND(INDEX($B$2:$HS$227,$A12+1,B$1)>0,INDEX($B$2:$HS$227,$A12,B$1+1)>0,INDEX($B$2:$HS$227,$A12*2,B$1)>0,INDEX($B$2:$HS$227,$A12,B$1*2)>0),-2,0) ,д!B12) -> 0 | C12: =IF(д!C12=0,IF(AND(INDEX($B$2:$HS$227,$A12+1,C$1)>0,INDEX($B$2:$HS$227,$A12,C$1+1)>0,INDEX($B$2:$HS$227,$A12*2,C$1)>0,INDEX($B$2:$HS$227,$A12,C$1*2)>0),-2,0) ,д!C12) -> 0 | D12: =IF(д!D12=0,IF(AND(INDEX($B$2:$HS$227,$A12+1,D$1)>0,INDEX($B$2:$HS$227,$A12,D$1+1)>0,INDEX($B$2:$HS$227,$A12*2,D$1)>0,INDEX($B$2:$HS$227,$A12,D$1*2)>0),-2,0) ,д!D12) -> 0 | E12: =IF(д!E12=0,IF(AND(INDEX($B$2:$HS$227,$A12+1,E$1)>0,INDEX($B$2:$HS$227,$A12,E$1+1)>0,INDEX($B$2:$HS$227,$A12*2,E$1)>0,INDEX($B$2:$HS$227,$A12,E$1*2)>0),-2,0) ,д!E12) -> 0 | F12: =IF(д!F12=0,IF(AND(INDEX($B$2:$HS$227,$A12+1,F$1)>0,INDEX($B$2:$HS$227,$A12,F$1+1)>0,INDEX($B$2:$HS$227,$A12*2,F$1)>0,INDEX($B$2:$HS$227,$A12,F$1*2)>0),-2,0) ,д!F12) -> 0 | G12: =IF(д!G12=0,IF(AND(INDEX($B$2:$HS$227,$A12+1,G$1)>0,INDEX($B$2:$HS$227,$A12,G$1+1)>0,INDEX($B$2:$HS$227,$A12*2,G$1)>0,INDEX($B$2:$HS$227,$A12,G$1*2)>0),-2,0) ,д!G12) -> 0 | H12: =IF(д!H12=0,IF(AND(INDEX($B$2:$HS$227,$A12+1,H$1)>0,INDEX($B$2:$HS$227,$A12,H$1+1)>0,INDEX($B$2:$HS$227,$A12*2,H$1)>0,INDEX($B$2:$HS$227,$A12,H$1*2)>0),-2,0) ,д!H12) -> 0 | I12: =IF(д!I12=0,IF(AND(INDEX($B$2:$HS$227,$A12+1,I$1)>0,INDEX($B$2:$HS$227,$A12,I$1+1)>0,INDEX($B$2:$HS$227,$A12*2,I$1)>0,INDEX($B$2:$HS$227,$A12,I$1*2)>0),-2,0) ,д!I12) -> 0 | ... DI12: =IF(д!DI12=0,IF(AND(INDEX($B$2:$HS$227,$A12+1,DI$1)>0,INDEX($B$2:$HS$227,$A12,DI$1+1)>0,INDEX($B$2:$HS$227,$A12*2,DI$1)>0,INDEX($B$2:$HS$227,$A12,DI$1*2)>0),-2,0) ,д!DI12) -> 1 | DJ12: =IF(д!DJ12=0,IF(OR(INDEX($B$2:$HS$227,$A12+1,DJ$1)<0,INDEX($B$2:$HS$227,$A12,DJ$1+1)<0,INDEX($B$2:$HS$227,$A12*2,DJ$1)<0,INDEX($B$2:$HS$227,$A12,DJ$1*2)<0),2,0) ,д!DJ12) -> 1 | DK12: =IF(д!DK12=0,IF(OR(INDEX($B$2:$HS$227,$A12+1,DK$1)>0,INDEX($B$2:$HS$227,$A12,DK$1+1)>0,INDEX($B$2:$HS$227,$A12*2,DK$1)>0,INDEX($B$2:$HS$227,$A12,DK$1*2)>0),-1,0) ,д!DK12) -> 1 | DL12: =IF(MAX(DL$1,$A12)*2 + MIN(DL$1,$A12) >= 227,1,0) -> 1 | DM12: =IF(MAX(DM$1,$A12)*2 + MIN(DM$1,$A12) >= 227,1,0) -> 1 | DN12: =IF(MAX(DN$1,$A12)*2 + MIN(DN$1,$A12) >= 227,1,0) -> 1 | DO12: =IF(MAX(DO$1,$A12)*2 + MIN(DO$1,$A12) >= 227,1,0) -> 1 | DP12: =IF(MAX(DP$1,$A12)*2 + MIN(DP$1,$A12) >= 227,1,0) -> 1 | DQ12: =IF(MAX(DQ$1,$A12)*2 + MIN(DQ$1,$A12) >= 227,1,0) -> 1 | DR12: =IF(MAX(DR$1,$A12)*2 + MIN(DR$1,$A12) >= 227,1,0) -> 1 | DS12: =IF(MAX(DS$1,$A12)*2 + MIN(DS$1,$A12) >= 227,1,0) -> 1 | ... HS12: =IF(MAX(HS$1,$A12)*2 + MIN(HS$1,$A12) >= 227,1,0) -> 1
A13: 12 | B13: =IF(д!B13=0,IF(AND(INDEX($B$2:$HS$227,$A13+1,B$1)>0,INDEX($B$2:$HS$227,$A13,B$1+1)>0,INDEX($B$2:$HS$227,$A13*2,B$1)>0,INDEX($B$2:$HS$227,$A13,B$1*2)>0),-2,0) ,д!B13) -> 0 | C13: =IF(д!C13=0,IF(AND(INDEX($B$2:$HS$227,$A13+1,C$1)>0,INDEX($B$2:$HS$227,$A13,C$1+1)>0,INDEX($B$2:$HS$227,$A13*2,C$1)>0,INDEX($B$2:$HS$227,$A13,C$1*2)>0),-2,0) ,д!C13) -> 0 | D13: =IF(д!D13=0,IF(AND(INDEX($B$2:$HS$227,$A13+1,D$1)>0,INDEX($B$2:$HS$227,$A13,D$1+1)>0,INDEX($B$2:$HS$227,$A13*2,D$1)>0,INDEX($B$2:$HS$227,$A13,D$1*2)>0),-2,0) ,д!D13) -> 0 | E13: =IF(д!E13=0,IF(AND(INDEX($B$2:$HS$227,$A13+1,E$1)>0,INDEX($B$2:$HS$227,$A13,E$1+1)>0,INDEX($B$2:$HS$227,$A13*2,E$1)>0,INDEX($B$2:$HS$227,$A13,E$1*2)>0),-2,0) ,д!E13) -> 0 | F13: =IF(д!F13=0,IF(AND(INDEX($B$2:$HS$227,$A13+1,F$1)>0,INDEX($B$2:$HS$227,$A13,F$1+1)>0,INDEX($B$2:$HS$227,$A13*2,F$1)>0,INDEX($B$2:$HS$227,$A13,F$1*2)>0),-2,0) ,д!F13) -> 0 | G13: =IF(д!G13=0,IF(AND(INDEX($B$2:$HS$227,$A13+1,G$1)>0,INDEX($B$2:$HS$227,$A13,G$1+1)>0,INDEX($B$2:$HS$227,$A13*2,G$1)>0,INDEX($B$2:$HS$227,$A13,G$1*2)>0),-2,0) ,д!G13) -> 0 | H13: =IF(д!H13=0,IF(AND(INDEX($B$2:$HS$227,$A13+1,H$1)>0,INDEX($B$2:$HS$227,$A13,H$1+1)>0,INDEX($B$2:$HS$227,$A13*2,H$1)>0,INDEX($B$2:$HS$227,$A13,H$1*2)>0),-2,0) ,д!H13) -> 0 | I13: =IF(д!I13=0,IF(AND(INDEX($B$2:$HS$227,$A13+1,I$1)>0,INDEX($B$2:$HS$227,$A13,I$1+1)>0,INDEX($B$2:$HS$227,$A13*2,I$1)>0,INDEX($B$2:$HS$227,$A13,I$1*2)>0),-2,0) ,д!I13) -> 0 | ... DI13: =IF(д!DI13=0,IF(AND(INDEX($B$2:$HS$227,$A13+1,DI$1)>0,INDEX($B$2:$HS$227,$A13,DI$1+1)>0,INDEX($B$2:$HS$227,$A13*2,DI$1)>0,INDEX($B$2:$HS$227,$A13,DI$1*2)>0),-2,0) ,д!DI13) -> 1 | DJ13: =IF(д!DJ13=0,IF(OR(INDEX($B$2:$HS$227,$A13+1,DJ$1)<0,INDEX($B$2:$HS$227,$A13,DJ$1+1)<0,INDEX($B$2:$HS$227,$A13*2,DJ$1)<0,INDEX($B$2:$HS$227,$A13,DJ$1*2)<0),2,0) ,д!DJ13) -> 1 | DK13: =IF(д!DK13=0,IF(OR(INDEX($B$2:$HS$227,$A13+1,DK$1)>0,INDEX($B$2:$HS$227,$A13,DK$1+1)>0,INDEX($B$2:$HS$227,$A13*2,DK$1)>0,INDEX($B$2:$HS$227,$A13,DK$1*2)>0),-1,0) ,д!DK13) -> 1 | DL13: =IF(MAX(DL$1,$A13)*2 + MIN(DL$1,$A13) >= 227,1,0) -> 1 | DM13: =IF(MAX(DM$1,$A13)*2 + MIN(DM$1,$A13) >= 227,1,0) -> 1 | DN13: =IF(MAX(DN$1,$A13)*2 + MIN(DN$1,$A13) >= 227,1,0) -> 1 | DO13: =IF(MAX(DO$1,$A13)*2 + MIN(DO$1,$A13) >= 227,1,0) -> 1 | DP13: =IF(MAX(DP$1,$A13)*2 + MIN(DP$1,$A13) >= 227,1,0) -> 1 | DQ13: =IF(MAX(DQ$1,$A13)*2 + MIN(DQ$1,$A13) >= 227,1,0) -> 1 | DR13: =IF(MAX(DR$1,$A13)*2 + MIN(DR$1,$A13) >= 227,1,0) -> 1 | DS13: =IF(MAX(DS$1,$A13)*2 + MIN(DS$1,$A13) >= 227,1,0) -> 1 | ... HS13: =IF(MAX(HS$1,$A13)*2 + MIN(HS$1,$A13) >= 227,1,0) -> 1
... A227: 226 | B227: =IF(д!B227=0,IF(AND(INDEX($B$2:$HS$227,$A227+1,B$1)>0,INDEX($B$2:$HS$227,$A227,B$1+1)>0,INDEX($B$2:$HS$227,$A227*2,B$1)>0,INDEX($B$2:$HS$227,$A227,B$1*2)>0),-2,0) ,д!B227) -> 1 | C227: =IF(д!C227=0,IF(AND(INDEX($B$2:$HS$227,$A227+1,C$1)>0,INDEX($B$2:$HS$227,$A227,C$1+1)>0,INDEX($B$2:$HS$227,$A227*2,C$1)>0,INDEX($B$2:$HS$227,$A227,C$1*2)>0),-2,0) ,д!C227) -> 1 | D227: =IF(д!D227=0,IF(AND(INDEX($B$2:$HS$227,$A227+1,D$1)>0,INDEX($B$2:$HS$227,$A227,D$1+1)>0,INDEX($B$2:$HS$227,$A227*2,D$1)>0,INDEX($B$2:$HS$227,$A227,D$1*2)>0),-2,0) ,д!D227) -> 1 | E227: =IF(д!E227=0,IF(AND(INDEX($B$2:$HS$227,$A227+1,E$1)>0,INDEX($B$2:$HS$227,$A227,E$1+1)>0,INDEX($B$2:$HS$227,$A227*2,E$1)>0,INDEX($B$2:$HS$227,$A227,E$1*2)>0),-2,0) ,д!E227) -> 1 | F227: =IF(д!F227=0,IF(AND(INDEX($B$2:$HS$227,$A227+1,F$1)>0,INDEX($B$2:$HS$227,$A227,F$1+1)>0,INDEX($B$2:$HS$227,$A227*2,F$1)>0,INDEX($B$2:$HS$227,$A227,F$1*2)>0),-2,0) ,д!F227) -> 1 | G227: =IF(д!G227=0,IF(AND(INDEX($B$2:$HS$227,$A227+1,G$1)>0,INDEX($B$2:$HS$227,$A227,G$1+1)>0,INDEX($B$2:$HS$227,$A227*2,G$1)>0,INDEX($B$2:$HS$227,$A227,G$1*2)>0),-2,0) ,д!G227) -> 1 | H227: =IF(д!H227=0,IF(AND(INDEX($B$2:$HS$227,$A227+1,H$1)>0,INDEX($B$2:$HS$227,$A227,H$1+1)>0,INDEX($B$2:$HS$227,$A227*2,H$1)>0,INDEX($B$2:$HS$227,$A227,H$1*2)>0),-2,0) ,д!H227) -> 1 | I227: =IF(д!I227=0,IF(AND(INDEX($B$2:$HS$227,$A227+1,I$1)>0,INDEX($B$2:$HS$227,$A227,I$1+1)>0,INDEX($B$2:$HS$227,$A227*2,I$1)>0,INDEX($B$2:$HS$227,$A227,I$1*2)>0),-2,0) ,д!I227) -> 1 | ... DI227: =IF(д!DI227=0,IF(AND(INDEX($B$2:$HS$227,$A227+1,DI$1)>0,INDEX($B$2:$HS$227,$A227,DI$1+1)>0,INDEX($B$2:$HS$227,$A227*2,DI$1)>0,INDEX($B$2:$HS$227,$A227,DI$1*2)>0),-2,0) ,д!DI227) -> 1 | DJ227: =IF(д!DJ227=0,IF(OR(INDEX($B$2:$HS$227,$A227+1,DJ$1)<0,INDEX($B$2:$HS$227,$A227,DJ$1+1)<0,INDEX($B$2:$HS$227,$A227*2,DJ$1)<0,INDEX($B$2:$HS$227,$A227,DJ$1*2)<0),2,0) ,д!DJ227) -> 1 | DK227: =IF(д!DK227=0,IF(OR(INDEX($B$2:$HS$227,$A227+1,DK$1)>0,INDEX($B$2:$HS$227,$A227,DK$1+1)>0,INDEX($B$2:$HS$227,$A227*2,DK$1)>0,INDEX($B$2:$HS$227,$A227,DK$1*2)>0),-1,0) ,д!DK227) -> 1 | DL227: =IF(MAX(DL$1,$A227)*2 + MIN(DL$1,$A227) >= 227,1,0) -> 1 | DM227: =IF(MAX(DM$1,$A227)*2 + MIN(DM$1,$A227) >= 227,1,0) -> 1 | DN227: =IF(MAX(DN$1,$A227)*2 + MIN(DN$1,$A227) >= 227,1,0) -> 1 | DO227: =IF(MAX(DO$1,$A227)*2 + MIN(DO$1,$A227) >= 227,1,0) -> 1 | DP227: =IF(MAX(DP$1,$A227)*2 + MIN(DP$1,$A227) >= 227,1,0) -> 1 | DQ227: =IF(MAX(DQ$1,$A227)*2 + MIN(DQ$1,$A227) >= 227,1,0) -> 1 | DR227: =IF(MAX(DR$1,$A227)*2 + MIN(DR$1,$A227) >= 227,1,0) -> 1 | DS227: =IF(MAX(DS$1,$A227)*2 + MIN(DS$1,$A227) >= 227,1,0) -> 1 | ... HS227: =IF(MAX(HS$1,$A227)*2 + MIN(HS$1,$A227) >= 227,1,0) -> 1

Sheet д
B1: 1 | C1: 2 | D1: 3 | E1: 4 | F1: 5 | G1: 6 | H1: 7 | I1: 8 | J1: 9 | K1: 10 | L1: 11 | M1: 12 | N1: 13 | O1: 14 | P1: 15 | Q1: 16 | R1: 17 | S1: 18 | T1: 19 | U1: 20 | V1: 21 | W1: 22 | X1: 23 | Y1: 24 | Z1: 25 | AA1: 26 | AB1: 27 | AC1: 28 | AD1: 29 | AE1: 30 | AF1: 31 | AG1: 32 | AH1: 33 | AI1: 34 | AJ1: 35 | AK1: 36 | AL1: 37 | AM1: 38 | AN1: 39 | AO1: 40 | AP1: 41 | AQ1: 42 | AR1: 43 | AS1: 44 | AT1: 45 | AU1: 46 | AV1: 47 | AW1: 48 | AX1: 49 | AY1: 50 | AZ1: 51 | BA1: 52 | BB1: 53 | BC1: 54 | BD1: 55 | BE1: 56 | BF1: 57 | BG1: 58 | BH1: 59 | BI1: 60 | BJ1: 61 | BK1: 62 | BL1: 63 | BM1: 64 | BN1: 65 | BO1: 66 | BP1: 67 | BQ1: 68 | BR1: 69 | BS1: 70 | BT1: 71 | BU1: 72 | BV1: 73 | BW1: 74 | BX1: 75 | BY1: 76 | BZ1: 77 | CA1: 78 | CB1: 79 | CC1: 80 | CD1: 81 | CE1: 82 | CF1: 83 | CG1: 84 | CH1: 85 | CI1: 86 | CJ1: 87 | CK1: 88 | CL1: 89 | CM1: 90 | CN1: 91 | CO1: 92 | CP1: 93 | CQ1: 94 | CR1: 95 | CS1: 96 | CT1: 97 | CU1: 98 | CV1: 99 | CW1: 100 | CX1: 101 | CY1: 102 | CZ1: 103 | DA1: 104 | DB1: 105 | DC1: 106 | DD1: 107 | DE1: 108 | DF1: 109 | DG1: 110 | DH1: 111 | DI1: 112 | DJ1: 113 | DK1: 114 | DL1: 115 | DM1: 116 | DN1: 117 | DO1: 118 | DP1: 119 | DQ1: 120 | DR1: 121 | DS1: 122 | DT1: 123 | DU1: 124 | DV1: 125 | DW1: 126 | DX1: 127 | DY1: 128 | DZ1: 129 | EA1: 130 | EB1: 131 | EC1: 132 | ED1: 133 | EE1: 134 | EF1: 135 | EG1: 136 | EH1: 137 | EI1: 138 | EJ1: 139 | EK1: 140 | EL1: 141 | EM1: 142 | EN1: 143 | EO1: 144 | EP1: 145 | EQ1: 146 | ER1: 147 | ES1: 148 | ET1: 149 | EU1: 150 | EV1: 151 | EW1: 152 | EX1: 153 | EY1: 154 | EZ1: 155 | FA1: 156 | FB1: 157 | FC1: 158 | FD1: 159 | FE1: 160 | FF1: 161 | FG1: 162 | FH1: 163 | FI1: 164 | FJ1: 165 | FK1: 166 | FL1: 167 | FM1: 168 | FN1: 169 | FO1: 170 | FP1: 171 | FQ1: 172 | FR1: 173 | FS1: 174 | FT1: 175 | FU1: 176 | FV1: 177 | FW1: 178 | FX1: 179 | FY1: 180 | FZ1: 181 | GA1: 182 | GB1: 183 | GC1: 184 | GD1: 185 | GE1: 186 | GF1: 187 | GG1: 188 | GH1: 189 | GI1: 190 | GJ1: 191 | GK1: 192 | GL1: 193 | GM1: 194 | GN1: 195 | GO1: 196 | GP1: 197 | GQ1: 198 | GR1: 199 | GS1: 200 | GT1: 201 | GU1: 202 | GV1: 203 | GW1: 204 | GX1: 205 | GY1: 206 | GZ1: 207 | HA1: 208 | HB1: 209 | HC1: 210 | HD1: 211 | HE1: 212 | HF1: 213 | HG1: 214 | HH1: 215 | HI1: 216 | HJ1: 217 | HK1: 218 | HL1: 219 | HM1: 220 | HN1: 221 | HO1: 222 | HP1: 223 | HQ1: 224 | HR1: 225 | HS1: 226
A2: 1 | B2: 0 | C2: 0 | D2: 0 | E2: 0 | F2: 0 | G2: 0 | H2: 0 | I2: 0 | J2: 0 | K2: 0 | L2: 0 | M2: 0 | N2: 0 | O2: 0 | P2: 0 | Q2: 0 | R2: 0 | S2: 0 | T2: 0 | U2: 0 | V2: 0 | W2: 0 | X2: 0 | Y2: 0 | Z2: 0 | AA2: 0 | AB2: 0 | AC2: 0 | AD2: 0 | AE2: 0 | AF2: 0 | AG2: 0 | AH2: 0 | AI2: 0 | AJ2: 0 | AK2: 0 | AL2: 0 | AM2: 0 | AN2: 0 | AO2: 0 | AP2: 0 | AQ2: 0 | AR2: 0 | AS2: 0 | AT2: 0 | AU2: 0 | AV2: 0 | AW2: 0 | AX2: 0 | AY2: 0 | AZ2: 0 | BA2: 0 | BB2: 0 | BC2: 0 | BD2: 0 | BE2: 0 | BF2: 0 | BG2: 0 | BH2: 0 | BI2: 0 | BJ2: 0 | BK2: 0 | BL2: 0 | BM2: 0 | BN2: 0 | BO2: 0 | BP2: 0 | BQ2: 0 | BR2: 0 | BS2: 0 | BT2: 0 | BU2: 0 | BV2: 0 | BW2: 0 | BX2: 0 | BY2: 0 | BZ2: 0 | CA2: 0 | CB2: 0 | CC2: 0 | CD2: 0 | CE2: 0 | CF2: 0 | CG2: 0 | CH2: 0 | CI2: 0 | CJ2: 0 | CK2: 0 | CL2: 0 | CM2: 0 | CN2: 0 | CO2: 0 | CP2: 0 | CQ2: 0 | CR2: 0 | CS2: 0 | CT2: 0 | CU2: 0 | CV2: 0 | CW2: 0 | CX2: 0 | CY2: 0 | CZ2: 0 | DA2: 0 | DB2: 0 | DC2: 0 | DD2: 0 | DE2: 0 | DF2: 0 | DG2: 0 | DH2: 0 | DI2: 2 | DJ2: 1 | DK2: 1 | DL2: 1 | DM2: 1 | DN2: 1 | DO2: 1 | DP2: 1 | DQ2: 1 | DR2: 1 | DS2: 1 | DT2: 1 | DU2: 1 | DV2: 1 | DW2: 1 | DX2: 1 | DY2: 1 | DZ2: 1 | EA2: 1 | EB2: 1 | EC2: 1 | ED2: 1 | EE2: 1 | EF2: 1 | EG2: 1 | EH2: 1 | EI2: 1 | EJ2: 1 | EK2: 1 | EL2: 1 | EM2: 1 | EN2: 1 | EO2: 1 | EP2: 1 | EQ2: 1 | ER2: 1 | ES2: 1 | ET2: 1 | EU2: 1 | EV2: 1 | EW2: 1 | EX2: 1 | EY2: 1 | EZ2: 1 | FA2: 1 | FB2: 1 | FC2: 1 | FD2: 1 | FE2: 1 | FF2: 1 | FG2: 1 | FH2: 1 | FI2: 1 | FJ2: 1 | FK2: 1 | FL2: 1 | FM2: 1 | FN2: 1 | FO2: 1 | FP2: 1 | FQ2: 1 | FR2: 1 | FS2: 1 | FT2: 1 | FU2: 1 | FV2: 1 | FW2: 1 | FX2: 1 | FY2: 1 | FZ2: 1 | GA2: 1 | GB2: 1 | GC2: 1 | GD2: 1 | GE2: 1 | GF2: 1 | GG2: 1 | GH2: 1 | GI2: 1 | GJ2: 1 | GK2: 1 | GL2: 1 | GM2: 1 | GN2: 1 | GO2: 1 | GP2: 1 | GQ2: 1 | GR2: 1 | GS2: 1 | GT2: 1 | GU2: 1 | GV2: 1 | GW2: 1 | GX2: 1 | GY2: 1 | GZ2: 1 | HA2: 1 | HB2: 1 | HC2: 1 | HD2: 1 | HE2: 1 | HF2: 1 | HG2: 1 | HH2: 1 | HI2: 1 | HJ2: 1 | HK2: 1 | HL2: 1 | HM2: 1 | HN2: 1 | HO2: 1 | HP2: 1 | HQ2: 1 | HR2: 1 | HS2: 1
A3: 2 | B3: 0 | C3: 0 | D3: 0 | E3: 0 | F3: 0 | G3: 0 | H3: 0 | I3: 0 | J3: 0 | K3: 0 | L3: 0 | M3: 0 | N3: 0 | O3: 0 | P3: 0 | Q3: 0 | R3: 0 | S3: 0 | T3: 0 | U3: 0 | V3: 0 | W3: 0 | X3: 0 | Y3: 0 | Z3: 0 | AA3: 0 | AB3: 0 | AC3: 0 | AD3: 0 | AE3: 0 | AF3: 0 | AG3: 0 | AH3: 0 | AI3: 0 | AJ3: 0 | AK3: 0 | AL3: 0 | AM3: 0 | AN3: 0 | AO3: 0 | AP3: 0 | AQ3: 0 | AR3: 0 | AS3: 0 | AT3: 0 | AU3: 0 | AV3: 0 | AW3: 0 | AX3: 0 | AY3: 0 | AZ3: 0 | BA3: 0 | BB3: 0 | BC3: 0 | BD3: 0 | BE3: 2 | BF3: 0 | BG3: 0 | BH3: 0 | BI3: 0 | BJ3: 0 | BK3: 0 | BL3: 0 | BM3: 0 | BN3: 0 | BO3: 0 | BP3: 0 | BQ3: 0 | BR3: 0 | BS3: 0 | BT3: 0 | BU3: 0 | BV3: 0 | BW3: 0 | BX3: 0 | BY3: 0 | BZ3: 0 | CA3: 0 | CB3: 0 | CC3: 0 | CD3: 0 | CE3: 0 | CF3: 0 | CG3: 0 | CH3: 0 | CI3: 0 | CJ3: 0 | CK3: 0 | CL3: 0 | CM3: 0 | CN3: 0 | CO3: 0 | CP3: 0 | CQ3: 0 | CR3: 0 | CS3: 0 | CT3: 0 | CU3: 0 | CV3: 0 | CW3: 0 | CX3: 0 | CY3: 0 | CZ3: 0 | DA3: 0 | DB3: 0 | DC3: 0 | DD3: 0 | DE3: 0 | DF3: 0 | DG3: 0 | DH3: 2 | DI3: -1 | DJ3: 1 | DK3: 1 | DL3: 1 | DM3: 1 | DN3: 1 | DO3: 1 | DP3: 1 | DQ3: 1 | DR3: 1 | DS3: 1 | DT3: 1 | DU3: 1 | DV3: 1 | DW3: 1 | DX3: 1 | DY3: 1 | DZ3: 1 | EA3: 1 | EB3: 1 | EC3: 1 | ED3: 1 | EE3: 1 | EF3: 1 | EG3: 1 | EH3: 1 | EI3: 1 | EJ3: 1 | EK3: 1 | EL3: 1 | EM3: 1 | EN3: 1 | EO3: 1 | EP3: 1 | EQ3: 1 | ER3: 1 | ES3: 1 | ET3: 1 | EU3: 1 | EV3: 1 | EW3: 1 | EX3: 1 | EY3: 1 | EZ3: 1 | FA3: 1 | FB3: 1 | FC3: 1 | FD3: 1 | FE3: 1 | FF3: 1 | FG3: 1 | FH3: 1 | FI3: 1 | FJ3: 1 | FK3: 1 | FL3: 1 | FM3: 1 | FN3: 1 | FO3: 1 | FP3: 1 | FQ3: 1 | FR3: 1 | FS3: 1 | FT3: 1 | FU3: 1 | FV3: 1 | FW3: 1 | FX3: 1 | FY3: 1 | FZ3: 1 | GA3: 1 | GB3: 1 | GC3: 1 | GD3: 1 | GE3: 1 | GF3: 1 | GG3: 1 | GH3: 1 | GI3: 1 | GJ3: 1 | GK3: 1 | GL3: 1 | GM3: 1 | GN3: 1 | GO3: 1 | GP3: 1 | GQ3: 1 | GR3: 1 | GS3: 1 | GT3: 1 | GU3: 1 | GV3: 1 | GW3: 1 | GX3: 1 | GY3: 1 | GZ3: 1 | HA3: 1 | HB3: 1 | HC3: 1 | HD3: 1 | HE3: 1 | HF3: 1 | HG3: 1 | HH3: 1 | HI3: 1 | HJ3: 1 | HK3: 1 | HL3: 1 | HM3: 1 | HN3: 1 | HO3: 1 | HP3: 1 | HQ3: 1 | HR3: 1 | HS3: 1
A4: 3 | B4: 0 | C4: 0 | D4: 0 | E4: 0 | F4: 0 | G4: 0 | H4: 0 | I4: 0 | J4: 0 | K4: 0 | L4: 0 | M4: 0 | N4: 0 | O4: 0 | P4: 0 | Q4: 0 | R4: 0 | S4: 0 | T4: 0 | U4: 0 | V4: 0 | W4: 0 | X4: 0 | Y4: 0 | Z4: 0 | AA4: 0 | AB4: 0 | AC4: 0 | AD4: 0 | AE4: 0 | AF4: 0 | AG4: 0 | AH4: 0 | AI4: 0 | AJ4: 0 | AK4: 0 | AL4: 0 | AM4: 0 | AN4: 0 | AO4: 0 | AP4: 0 | AQ4: 0 | AR4: 0 | AS4: 0 | AT4: 0 | AU4: 0 | AV4: 0 | AW4: 0 | AX4: 0 | AY4: 0 | AZ4: 0 | BA4: 0 | BB4: 0 | BC4: 0 | BD4: 0 | BE4: 0 | BF4: 0 | BG4: 0 | BH4: 0 | BI4: 0 | BJ4: 0 | BK4: 0 | BL4: 0 | BM4: 0 | BN4: 0 | BO4: 0 | BP4: 0 | BQ4: 0 | BR4: 0 | BS4: 0 | BT4: 0 | BU4: 0 | BV4: 0 | BW4: 0 | BX4: 0 | BY4: 0 | BZ4: 0 | CA4: 0 | CB4: 0 | CC4: 0 | CD4: 0 | CE4: 0 | CF4: 0 | CG4: 0 | CH4: 0 | CI4: 0 | CJ4: 0 | CK4: 0 | CL4: 0 | CM4: 0 | CN4: 0 | CO4: 0 | CP4: 0 | CQ4: 0 | CR4: 0 | CS4: 0 | CT4: 0 | CU4: 0 | CV4: 0 | CW4: 0 | CX4: 0 | CY4: 0 | CZ4: 0 | DA4: 0 | DB4: 0 | DC4: 0 | DD4: 0 | DE4: 0 | DF4: 0 | DG4: 2 | DH4: 2 | DI4: 1 | DJ4: 1 | DK4: 1 | DL4: 1 | DM4: 1 | DN4: 1 | DO4: 1 | DP4: 1 | DQ4: 1 | DR4: 1 | DS4: 1 | DT4: 1 | DU4: 1 | DV4: 1 | DW4: 1 | DX4: 1 | DY4: 1 | DZ4: 1 | EA4: 1 | EB4: 1 | EC4: 1 | ED4: 1 | EE4: 1 | EF4: 1 | EG4: 1 | EH4: 1 | EI4: 1 | EJ4: 1 | EK4: 1 | EL4: 1 | EM4: 1 | EN4: 1 | EO4: 1 | EP4: 1 | EQ4: 1 | ER4: 1 | ES4: 1 | ET4: 1 | EU4: 1 | EV4: 1 | EW4: 1 | EX4: 1 | EY4: 1 | EZ4: 1 | FA4: 1 | FB4: 1 | FC4: 1 | FD4: 1 | FE4: 1 | FF4: 1 | FG4: 1 | FH4: 1 | FI4: 1 | FJ4: 1 | FK4: 1 | FL4: 1 | FM4: 1 | FN4: 1 | FO4: 1 | FP4: 1 | FQ4: 1 | FR4: 1 | FS4: 1 | FT4: 1 | FU4: 1 | FV4: 1 | FW4: 1 | FX4: 1 | FY4: 1 | FZ4: 1 | GA4: 1 | GB4: 1 | GC4: 1 | GD4: 1 | GE4: 1 | GF4: 1 | GG4: 1 | GH4: 1 | GI4: 1 | GJ4: 1 | GK4: 1 | GL4: 1 | GM4: 1 | GN4: 1 | GO4: 1 | GP4: 1 | GQ4: 1 | GR4: 1 | GS4: 1 | GT4: 1 | GU4: 1 | GV4: 1 | GW4: 1 | GX4: 1 | GY4: 1 | GZ4: 1 | HA4: 1 | HB4: 1 | HC4: 1 | HD4: 1 | HE4: 1 | HF4: 1 | HG4: 1 | HH4: 1 | HI4: 1 | HJ4: 1 | HK4: 1 | HL4: 1 | HM4: 1 | HN4: 1 | HO4: 1 | HP4: 1 | HQ4: 1 | HR4: 1 | HS4: 1
A5: 4 | B5: 0 | C5: 0 | D5: 0 | E5: 0 | F5: 0 | G5: 0 | H5: 0 | I5: 0 | J5: 0 | K5: 0 | L5: 0 | M5: 0 | N5: 0 | O5: 0 | P5: 0 | Q5: 0 | R5: 0 | S5: 0 | T5: 0 | U5: 0 | V5: 0 | W5: 0 | X5: 0 | Y5: 0 | Z5: 0 | AA5: 0 | AB5: 0 | AC5: 0 | AD5: 0 | AE5: 0 | AF5: 0 | AG5: 0 | AH5: 0 | AI5: 0 | AJ5: 0 | AK5: 0 | AL5: 0 | AM5: 0 | AN5: 0 | AO5: 0 | AP5: 0 | AQ5: 0 | AR5: 0 | AS5: 0 | AT5: 0 | AU5: 0 | AV5: 0 | AW5: 0 | AX5: 0 | AY5: 0 | AZ5: 0 | BA5: 0 | BB5: 0 | BC5: 0 | BD5: 0 | BE5: 0 | BF5: 0 | BG5: 0 | BH5: 0 | BI5: 0 | BJ5: 0 | BK5: 0 | BL5: 0 | BM5: 0 | BN5: 0 | BO5: 0 | BP5: 0 | BQ5: 0 | BR5: 0 | BS5: 0 | BT5: 0 | BU5: 0 | BV5: 0 | BW5: 0 | BX5: 0 | BY5: 0 | BZ5: 0 | CA5: 0 | CB5: 0 | CC5: 0 | CD5: 0 | CE5: 0 | CF5: 0 | CG5: 0 | CH5: 0 | CI5: 0 | CJ5: 0 | CK5: 0 | CL5: 0 | CM5: 0 | CN5: 0 | CO5: 0 | CP5: 0 | CQ5: 0 | CR5: 0 | CS5: 0 | CT5: 0 | CU5: 0 | CV5: 0 | CW5: 0 | CX5: 0 | CY5: 0 | CZ5: 0 | DA5: 0 | DB5: 0 | DC5: 0 | DD5: 0 | DE5: 0 | DF5: 2 | DG5: 2 | DH5: -1 | DI5: 1 | DJ5: 1 | DK5: 1 | DL5: 1 | DM5: 1 | DN5: 1 | DO5: 1 | DP5: 1 | DQ5: 1 | DR5: 1 | DS5: 1 | DT5: 1 | DU5: 1 | DV5: 1 | DW5: 1 | DX5: 1 | DY5: 1 | DZ5: 1 | EA5: 1 | EB5: 1 | EC5: 1 | ED5: 1 | EE5: 1 | EF5: 1 | EG5: 1 | EH5: 1 | EI5: 1 | EJ5: 1 | EK5: 1 | EL5: 1 | EM5: 1 | EN5: 1 | EO5: 1 | EP5: 1 | EQ5: 1 | ER5: 1 | ES5: 1 | ET5: 1 | EU5: 1 | EV5: 1 | EW5: 1 | EX5: 1 | EY5: 1 | EZ5: 1 | FA5: 1 | FB5: 1 | FC5: 1 | FD5: 1 | FE5: 1 | FF5: 1 | FG5: 1 | FH5: 1 | FI5: 1 | FJ5: 1 | FK5: 1 | FL5: 1 | FM5: 1 | FN5: 1 | FO5: 1 | FP5: 1 | FQ5: 1 | FR5: 1 | FS5: 1 | FT5: 1 | FU5: 1 | FV5: 1 | FW5: 1 | FX5: 1 | FY5: 1 | FZ5: 1 | GA5: 1 | GB5: 1 | GC5: 1 | GD5: 1 | GE5: 1 | GF5: 1 | GG5: 1 | GH5: 1 | GI5: 1 | GJ5: 1 | GK5: 1 | GL5: 1 | GM5: 1 | GN5: 1 | GO5: 1 | GP5: 1 | GQ5: 1 | GR5: 1 | GS5: 1 | GT5: 1 | GU5: 1 | GV5: 1 | GW5: 1 | GX5: 1 | GY5: 1 | GZ5: 1 | HA5: 1 | HB5: 1 | HC5: 1 | HD5: 1 | HE5: 1 | HF5: 1 | HG5: 1 | HH5: 1 | HI5: 1 | HJ5: 1 | HK5: 1 | HL5: 1 | HM5: 1 | HN5: 1 | HO5: 1 | HP5: 1 | HQ5: 1 | HR5: 1 | HS5: 1
A6: 5 | B6: 0 | C6: 0 | D6: 0 | E6: 0 | F6: 0 | G6: 0 | H6: 0 | I6: 0 | J6: 0 | K6: 0 | L6: 0 | M6: 0 | N6: 0 | O6: 0 | P6: 0 | Q6: 0 | R6: 0 | S6: 0 | T6: 0 | U6: 0 | V6: 0 | W6: 0 | X6: 0 | Y6: 0 | Z6: 0 | AA6: 0 | AB6: 0 | AC6: 0 | AD6: 0 | AE6: 0 | AF6: 0 | AG6: 0 | AH6: 0 | AI6: 0 | AJ6: 0 | AK6: 0 | AL6: 0 | AM6: 0 | AN6: 0 | AO6: 0 | AP6: 0 | AQ6: 0 | AR6: 0 | AS6: 0 | AT6: 0 | AU6: 0 | AV6: 0 | AW6: 0 | AX6: 0 | AY6: 0 | AZ6: 0 | BA6: 0 | BB6: 0 | BC6: 0 | BD6: 0 | BE6: 0 | BF6: 0 | BG6: 0 | BH6: 0 | BI6: 0 | BJ6: 0 | BK6: 0 | BL6: 0 | BM6: 0 | BN6: 0 | BO6: 0 | BP6: 0 | BQ6: 0 | BR6: 0 | BS6: 0 | BT6: 0 | BU6: 0 | BV6: 0 | BW6: 0 | BX6: 0 | BY6: 0 | BZ6: 0 | CA6: 0 | CB6: 0 | CC6: 0 | CD6: 0 | CE6: 0 | CF6: 0 | CG6: 0 | CH6: 0 | CI6: 0 | CJ6: 0 | CK6: 0 | CL6: 0 | CM6: 0 | CN6: 0 | CO6: 0 | CP6: 0 | CQ6: 0 | CR6: 0 | CS6: 0 | CT6: 0 | CU6: 0 | CV6: 0 | CW6: 0 | CX6: 0 | CY6: 0 | CZ6: 0 | DA6: 0 | DB6: 0 | DC6: 0 | DD6: 0 | DE6: 2 | DF6: 0 | DG6: 2 | DH6: 1 | DI6: 1 | DJ6: 1 | DK6: 1 | DL6: 1 | DM6: 1 | DN6: 1 | DO6: 1 | DP6: 1 | DQ6: 1 | DR6: 1 | DS6: 1 | DT6: 1 | DU6: 1 | DV6: 1 | DW6: 1 | DX6: 1 | DY6: 1 | DZ6: 1 | EA6: 1 | EB6: 1 | EC6: 1 | ED6: 1 | EE6: 1 | EF6: 1 | EG6: 1 | EH6: 1 | EI6: 1 | EJ6: 1 | EK6: 1 | EL6: 1 | EM6: 1 | EN6: 1 | EO6: 1 | EP6: 1 | EQ6: 1 | ER6: 1 | ES6: 1 | ET6: 1 | EU6: 1 | EV6: 1 | EW6: 1 | EX6: 1 | EY6: 1 | EZ6: 1 | FA6: 1 | FB6: 1 | FC6: 1 | FD6: 1 | FE6: 1 | FF6: 1 | FG6: 1 | FH6: 1 | FI6: 1 | FJ6: 1 | FK6: 1 | FL6: 1 | FM6: 1 | FN6: 1 | FO6: 1 | FP6: 1 | FQ6: 1 | FR6: 1 | FS6: 1 | FT6: 1 | FU6: 1 | FV6: 1 | FW6: 1 | FX6: 1 | FY6: 1 | FZ6: 1 | GA6: 1 | GB6: 1 | GC6: 1 | GD6: 1 | GE6: 1 | GF6: 1 | GG6: 1 | GH6: 1 | GI6: 1 | GJ6: 1 | GK6: 1 | GL6: 1 | GM6: 1 | GN6: 1 | GO6: 1 | GP6: 1 | GQ6: 1 | GR6: 1 | GS6: 1 | GT6: 1 | GU6: 1 | GV6: 1 | GW6: 1 | GX6: 1 | GY6: 1 | GZ6: 1 | HA6: 1 | HB6: 1 | HC6: 1 | HD6: 1 | HE6: 1 | HF6: 1 | HG6: 1 | HH6: 1 | HI6: 1 | HJ6: 1 | HK6: 1 | HL6: 1 | HM6: 1 | HN6: 1 | HO6: 1 | HP6: 1 | HQ6: 1 | HR6: 1 | HS6: 1
A7: 6 | B7: 0 | C7: 0 | D7: 0 | E7: 0 | F7: 0 | G7: 0 | H7: 0 | I7: 0 | J7: 0 | K7: 0 | L7: 0 | M7: 0 | N7: 0 | O7: 0 | P7: 0 | Q7: 0 | R7: 0 | S7: 0 | T7: 0 | U7: 0 | V7: 0 | W7: 0 | X7: 0 | Y7: 0 | Z7: 0 | AA7: 0 | AB7: 0 | AC7: 0 | AD7: 0 | AE7: 0 | AF7: 0 | AG7: 0 | AH7: 0 | AI7: 0 | AJ7: 0 | AK7: 0 | AL7: 0 | AM7: 0 | AN7: 0 | AO7: 0 | AP7: 0 | AQ7: 0 | AR7: 0 | AS7: 0 | AT7: 0 | AU7: 0 | AV7: 0 | AW7: 0 | AX7: 0 | AY7: 0 | AZ7: 0 | BA7: 0 | BB7: 0 | BC7: 0 | BD7: 2 | BE7: 0 | BF7: 0 | BG7: 0 | BH7: 0 | BI7: 0 | BJ7: 0 | BK7: 0 | BL7: 0 | BM7: 0 | BN7: 0 | BO7: 0 | BP7: 0 | BQ7: 0 | BR7: 0 | BS7: 0 | BT7: 0 | BU7: 0 | BV7: 0 | BW7: 0 | BX7: 0 | BY7: 0 | BZ7: 0 | CA7: 0 | CB7: 0 | CC7: 0 | CD7: 0 | CE7: 0 | CF7: 0 | CG7: 0 | CH7: 0 | CI7: 0 | CJ7: 0 | CK7: 0 | CL7: 0 | CM7: 0 | CN7: 0 | CO7: 0 | CP7: 0 | CQ7: 0 | CR7: 0 | CS7: 0 | CT7: 0 | CU7: 0 | CV7: 0 | CW7: 0 | CX7: 0 | CY7: 0 | CZ7: 0 | DA7: 0 | DB7: 0 | DC7: 0 | DD7: 2 | DE7: 0 | DF7: 2 | DG7: -1 | DH7: 1 | DI7: 1 | DJ7: 1 | DK7: 1 | DL7: 1 | DM7: 1 | DN7: 1 | DO7: 1 | DP7: 1 | DQ7: 1 | DR7: 1 | DS7: 1 | DT7: 1 | DU7: 1 | DV7: 1 | DW7: 1 | DX7: 1 | DY7: 1 | DZ7: 1 | EA7: 1 | EB7: 1 | EC7: 1 | ED7: 1 | EE7: 1 | EF7: 1 | EG7: 1 | EH7: 1 | EI7: 1 | EJ7: 1 | EK7: 1 | EL7: 1 | EM7: 1 | EN7: 1 | EO7: 1 | EP7: 1 | EQ7: 1 | ER7: 1 | ES7: 1 | ET7: 1 | EU7: 1 | EV7: 1 | EW7: 1 | EX7: 1 | EY7: 1 | EZ7: 1 | FA7: 1 | FB7: 1 | FC7: 1 | FD7: 1 | FE7: 1 | FF7: 1 | FG7: 1 | FH7: 1 | FI7: 1 | FJ7: 1 | FK7: 1 | FL7: 1 | FM7: 1 | FN7: 1 | FO7: 1 | FP7: 1 | FQ7: 1 | FR7: 1 | FS7: 1 | FT7: 1 | FU7: 1 | FV7: 1 | FW7: 1 | FX7: 1 | FY7: 1 | FZ7: 1 | GA7: 1 | GB7: 1 | GC7: 1 | GD7: 1 | GE7: 1 | GF7: 1 | GG7: 1 | GH7: 1 | GI7: 1 | GJ7: 1 | GK7: 1 | GL7: 1 | GM7: 1 | GN7: 1 | GO7: 1 | GP7: 1 | GQ7: 1 | GR7: 1 | GS7: 1 | GT7: 1 | GU7: 1 | GV7: 1 | GW7: 1 | GX7: 1 | GY7: 1 | GZ7: 1 | HA7: 1 | HB7: 1 | HC7: 1 | HD7: 1 | HE7: 1 | HF7: 1 | HG7: 1 | HH7: 1 | HI7: 1 | HJ7: 1 | HK7: 1 | HL7: 1 | HM7: 1 | HN7: 1 | HO7: 1 | HP7: 1 | HQ7: 1 | HR7: 1 | HS7: 1
A8: 7 | B8: 0 | C8: 0 | D8: 0 | E8: 0 | F8: 0 | G8: 0 | H8: 0 | I8: 0 | J8: 0 | K8: 0 | L8: 0 | M8: 0 | N8: 0 | O8: 0 | P8: 0 | Q8: 0 | R8: 0 | S8: 0 | T8: 0 | U8: 0 | V8: 0 | W8: 0 | X8: 0 | Y8: 0 | Z8: 0 | AA8: 0 | AB8: 0 | AC8: 0 | AD8: 0 | AE8: 0 | AF8: 0 | AG8: 0 | AH8: 0 | AI8: 0 | AJ8: 0 | AK8: 0 | AL8: 0 | AM8: 0 | AN8: 0 | AO8: 0 | AP8: 0 | AQ8: 0 | AR8: 0 | AS8: 0 | AT8: 0 | AU8: 0 | AV8: 0 | AW8: 0 | AX8: 0 | AY8: 0 | AZ8: 0 | BA8: 0 | BB8: 0 | BC8: 0 | BD8: 0 | BE8: 0 | BF8: 0 | BG8: 0 | BH8: 0 | BI8: 0 | BJ8: 0 | BK8: 0 | BL8: 0 | BM8: 0 | BN8: 0 | BO8: 0 | BP8: 0 | BQ8: 0 | BR8: 0 | BS8: 0 | BT8: 0 | BU8: 0 | BV8: 0 | BW8: 0 | BX8: 0 | BY8: 0 | BZ8: 0 | CA8: 0 | CB8: 0 | CC8: 0 | CD8: 0 | CE8: 0 | CF8: 0 | CG8: 0 | CH8: 0 | CI8: 0 | CJ8: 0 | CK8: 0 | CL8: 0 | CM8: 0 | CN8: 0 | CO8: 0 | CP8: 0 | CQ8: 0 | CR8: 0 | CS8: 0 | CT8: 0 | CU8: 0 | CV8: 0 | CW8: 0 | CX8: 0 | CY8: 0 | CZ8: 0 | DA8: 0 | DB8: 0 | DC8: 2 | DD8: 0 | DE8: 0 | DF8: 2 | DG8: 1 | DH8: 1 | DI8: 1 | DJ8: 1 | DK8: 1 | DL8: 1 | DM8: 1 | DN8: 1 | DO8: 1 | DP8: 1 | DQ8: 1 | DR8: 1 | DS8: 1 | DT8: 1 | DU8: 1 | DV8: 1 | DW8: 1 | DX8: 1 | DY8: 1 | DZ8: 1 | EA8: 1 | EB8: 1 | EC8: 1 | ED8: 1 | EE8: 1 | EF8: 1 | EG8: 1 | EH8: 1 | EI8: 1 | EJ8: 1 | EK8: 1 | EL8: 1 | EM8: 1 | EN8: 1 | EO8: 1 | EP8: 1 | EQ8: 1 | ER8: 1 | ES8: 1 | ET8: 1 | EU8: 1 | EV8: 1 | EW8: 1 | EX8: 1 | EY8: 1 | EZ8: 1 | FA8: 1 | FB8: 1 | FC8: 1 | FD8: 1 | FE8: 1 | FF8: 1 | FG8: 1 | FH8: 1 | FI8: 1 | FJ8: 1 | FK8: 1 | FL8: 1 | FM8: 1 | FN8: 1 | FO8: 1 | FP8: 1 | FQ8: 1 | FR8: 1 | FS8: 1 | FT8: 1 | FU8: 1 | FV8: 1 | FW8: 1 | FX8: 1 | FY8: 1 | FZ8: 1 | GA8: 1 | GB8: 1 | GC8: 1 | GD8: 1 | GE8: 1 | GF8: 1 | GG8: 1 | GH8: 1 | GI8: 1 | GJ8: 1 | GK8: 1 | GL8: 1 | GM8: 1 | GN8: 1 | GO8: 1 | GP8: 1 | GQ8: 1 | GR8: 1 | GS8: 1 | GT8: 1 | GU8: 1 | GV8: 1 | GW8: 1 | GX8: 1 | GY8: 1 | GZ8: 1 | HA8: 1 | HB8: 1 | HC8: 1 | HD8: 1 | HE8: 1 | HF8: 1 | HG8: 1 | HH8: 1 | HI8: 1 | HJ8: 1 | HK8: 1 | HL8: 1 | HM8: 1 | HN8: 1 | HO8: 1 | HP8: 1 | HQ8: 1 | HR8: 1 | HS8: 1
A9: 8 | B9: 0 | C9: 0 | D9: 0 | E9: 0 | F9: 0 | G9: 0 | H9: 0 | I9: 0 | J9: 0 | K9: 0 | L9: 0 | M9: 0 | N9: 0 | O9: 0 | P9: 0 | Q9: 0 | R9: 0 | S9: 0 | T9: 0 | U9: 0 | V9: 0 | W9: 0 | X9: 0 | Y9: 0 | Z9: 0 | AA9: 0 | AB9: 0 | AC9: 0 | AD9: 0 | AE9: 0 | AF9: 0 | AG9: 0 | AH9: 0 | AI9: 0 | AJ9: 0 | AK9: 0 | AL9: 0 | AM9: 0 | AN9: 0 | AO9: 0 | AP9: 0 | AQ9: 0 | AR9: 0 | AS9: 0 | AT9: 0 | AU9: 0 | AV9: 0 | AW9: 0 | AX9: 0 | AY9: 0 | AZ9: 0 | BA9: 0 | BB9: 0 | BC9: 0 | BD9: 0 | BE9: 0 | BF9: 0 | BG9: 0 | BH9: 0 | BI9: 0 | BJ9: 0 | BK9: 0 | BL9: 0 | BM9: 0 | BN9: 0 | BO9: 0 | BP9: 0 | BQ9: 0 | BR9: 0 | BS9: 0 | BT9: 0 | BU9: 0 | BV9: 0 | BW9: 0 | BX9: 0 | BY9: 0 | BZ9: 0 | CA9: 0 | CB9: 0 | CC9: 0 | CD9: 0 | CE9: 0 | CF9: 0 | CG9: 0 | CH9: 0 | CI9: 0 | CJ9: 0 | CK9: 0 | CL9: 0 | CM9: 0 | CN9: 0 | CO9: 0 | CP9: 0 | CQ9: 0 | CR9: 0 | CS9: 0 | CT9: 0 | CU9: 0 | CV9: 0 | CW9: 0 | CX9: 0 | CY9: 0 | CZ9: 0 | DA9: 0 | DB9: 2 | DC9: 0 | DD9: 0 | DE9: 2 | DF9: -1 | DG9: 1 | DH9: 1 | DI9: 1 | DJ9: 1 | DK9: 1 | DL9: 1 | DM9: 1 | DN9: 1 | DO9: 1 | DP9: 1 | DQ9: 1 | DR9: 1 | DS9: 1 | DT9: 1 | DU9: 1 | DV9: 1 | DW9: 1 | DX9: 1 | DY9: 1 | DZ9: 1 | EA9: 1 | EB9: 1 | EC9: 1 | ED9: 1 | EE9: 1 | EF9: 1 | EG9: 1 | EH9: 1 | EI9: 1 | EJ9: 1 | EK9: 1 | EL9: 1 | EM9: 1 | EN9: 1 | EO9: 1 | EP9: 1 | EQ9: 1 | ER9: 1 | ES9: 1 | ET9: 1 | EU9: 1 | EV9: 1 | EW9: 1 | EX9: 1 | EY9: 1 | EZ9: 1 | FA9: 1 | FB9: 1 | FC9: 1 | FD9: 1 | FE9: 1 | FF9: 1 | FG9: 1 | FH9: 1 | FI9: 1 | FJ9: 1 | FK9: 1 | FL9: 1 | FM9: 1 | FN9: 1 | FO9: 1 | FP9: 1 | FQ9: 1 | FR9: 1 | FS9: 1 | FT9: 1 | FU9: 1 | FV9: 1 | FW9: 1 | FX9: 1 | FY9: 1 | FZ9: 1 | GA9: 1 | GB9: 1 | GC9: 1 | GD9: 1 | GE9: 1 | GF9: 1 | GG9: 1 | GH9: 1 | GI9: 1 | GJ9: 1 | GK9: 1 | GL9: 1 | GM9: 1 | GN9: 1 | GO9: 1 | GP9: 1 | GQ9: 1 | GR9: 1 | GS9: 1 | GT9: 1 | GU9: 1 | GV9: 1 | GW9: 1 | GX9: 1 | GY9: 1 | GZ9: 1 | HA9: 1 | HB9: 1 | HC9: 1 | HD9: 1 | HE9: 1 | HF9: 1 | HG9: 1 | HH9: 1 | HI9: 1 | HJ9: 1 | HK9: 1 | HL9: 1 | HM9: 1 | HN9: 1 | HO9: 1 | HP9: 1 | HQ9: 1 | HR9: 1 | HS9: 1
A10: 9 | B10: 0 | C10: 0 | D10: 0 | E10: 0 | F10: 0 | G10: 0 | H10: 0 | I10: 0 | J10: 0 | K10: 0 | L10: 0 | M10: 0 | N10: 0 | O10: 0 | P10: 0 | Q10: 0 | R10: 0 | S10: 0 | T10: 0 | U10: 0 | V10: 0 | W10: 0 | X10: 0 | Y10: 0 | Z10: 0 | AA10: 0 | AB10: 0 | AC10: 0 | AD10: 0 | AE10: 0 | AF10: 0 | AG10: 0 | AH10: 0 | AI10: 0 | AJ10: 0 | AK10: 0 | AL10: 0 | AM10: 0 | AN10: 0 | AO10: 0 | AP10: 0 | AQ10: 0 | AR10: 0 | AS10: 0 | AT10: 0 | AU10: 0 | AV10: 0 | AW10: 0 | AX10: 0 | AY10: 0 | AZ10: 0 | BA10: 0 | BB10: 0 | BC10: 0 | BD10: 0 | BE10: 0 | BF10: 0 | BG10: 0 | BH10: 0 | BI10: 0 | BJ10: 0 | BK10: 0 | BL10: 0 | BM10: 0 | BN10: 0 | BO10: 0 | BP10: 0 | BQ10: 0 | BR10: 0 | BS10: 0 | BT10: 0 | BU10: 0 | BV10: 0 | BW10: 0 | BX10: 0 | BY10: 0 | BZ10: 0 | CA10: 0 | CB10: 0 | CC10: 0 | CD10: 0 | CE10: 0 | CF10: 0 | CG10: 0 | CH10: 0 | CI10: 0 | CJ10: 0 | CK10: 0 | CL10: 0 | CM10: 0 | CN10: 0 | CO10: 0 | CP10: 0 | CQ10: 0 | CR10: 0 | CS10: 0 | CT10: 0 | CU10: 0 | CV10: 0 | CW10: 0 | CX10: 0 | CY10: 0 | CZ10: 0 | DA10: 2 | DB10: 0 | DC10: 0 | DD10: 0 | DE10: 2 | DF10: 1 | DG10: 1 | DH10: 1 | DI10: 1 | DJ10: 1 | DK10: 1 | DL10: 1 | DM10: 1 | DN10: 1 | DO10: 1 | DP10: 1 | DQ10: 1 | DR10: 1 | DS10: 1 | DT10: 1 | DU10: 1 | DV10: 1 | DW10: 1 | DX10: 1 | DY10: 1 | DZ10: 1 | EA10: 1 | EB10: 1 | EC10: 1 | ED10: 1 | EE10: 1 | EF10: 1 | EG10: 1 | EH10: 1 | EI10: 1 | EJ10: 1 | EK10: 1 | EL10: 1 | EM10: 1 | EN10: 1 | EO10: 1 | EP10: 1 | EQ10: 1 | ER10: 1 | ES10: 1 | ET10: 1 | EU10: 1 | EV10: 1 | EW10: 1 | EX10: 1 | EY10: 1 | EZ10: 1 | FA10: 1 | FB10: 1 | FC10: 1 | FD10: 1 | FE10: 1 | FF10: 1 | FG10: 1 | FH10: 1 | FI10: 1 | FJ10: 1 | FK10: 1 | FL10: 1 | FM10: 1 | FN10: 1 | FO10: 1 | FP10: 1 | FQ10: 1 | FR10: 1 | FS10: 1 | FT10: 1 | FU10: 1 | FV10: 1 | FW10: 1 | FX10: 1 | FY10: 1 | FZ10: 1 | GA10: 1 | GB10: 1 | GC10: 1 | GD10: 1 | GE10: 1 | GF10: 1 | GG10: 1 | GH10: 1 | GI10: 1 | GJ10: 1 | GK10: 1 | GL10: 1 | GM10: 1 | GN10: 1 | GO10: 1 | GP10: 1 | GQ10: 1 | GR10: 1 | GS10: 1 | GT10: 1 | GU10: 1 | GV10: 1 | GW10: 1 | GX10: 1 | GY10: 1 | GZ10: 1 | HA10: 1 | HB10: 1 | HC10: 1 | HD10: 1 | HE10: 1 | HF10: 1 | HG10: 1 | HH10: 1 | HI10: 1 | HJ10: 1 | HK10: 1 | HL10: 1 | HM10: 1 | HN10: 1 | HO10: 1 | HP10: 1 | HQ10: 1 | HR10: 1 | HS10: 1
A11: 10 | B11: 0 | C11: 0 | D11: 0 | E11: 0 | F11: 0 | G11: 0 | H11: 0 | I11: 0 | J11: 0 | K11: 0 | L11: 0 | M11: 0 | N11: 0 | O11: 0 | P11: 0 | Q11: 0 | R11: 0 | S11: 0 | T11: 0 | U11: 0 | V11: 0 | W11: 0 | X11: 0 | Y11: 0 | Z11: 0 | AA11: 0 | AB11: 0 | AC11: 0 | AD11: 0 | AE11: 0 | AF11: 0 | AG11: 0 | AH11: 0 | AI11: 0 | AJ11: 0 | AK11: 0 | AL11: 0 | AM11: 0 | AN11: 0 | AO11: 0 | AP11: 0 | AQ11: 0 | AR11: 0 | AS11: 0 | AT11: 0 | AU11: 0 | AV11: 0 | AW11: 0 | AX11: 0 | AY11: 0 | AZ11: 0 | BA11: 0 | BB11: 0 | BC11: 2 | BD11: 0 | BE11: 0 | BF11: 0 | BG11: 0 | BH11: 0 | BI11: 0 | BJ11: 0 | BK11: 0 | BL11: 0 | BM11: 0 | BN11: 0 | BO11: 0 | BP11: 0 | BQ11: 0 | BR11: 0 | BS11: 0 | BT11: 0 | BU11: 0 | BV11: 0 | BW11: 0 | BX11: 0 | BY11: 0 | BZ11: 0 | CA11: 0 | CB11: 0 | CC11: 0 | CD11: 0 | CE11: 0 | CF11: 0 | CG11: 0 | CH11: 0 | CI11: 0 | CJ11: 0 | CK11: 0 | CL11: 0 | CM11: 0 | CN11: 0 | CO11: 0 | CP11: 0 | CQ11: 0 | CR11: 0 | CS11: 0 | CT11: 0 | CU11: 0 | CV11: 0 | CW11: 0 | CX11: 0 | CY11: 0 | CZ11: 2 | DA11: 0 | DB11: 0 | DC11: 0 | DD11: 2 | DE11: -1 | DF11: 1 | DG11: 1 | DH11: 1 | DI11: 1 | DJ11: 1 | DK11: 1 | DL11: 1 | DM11: 1 | DN11: 1 | DO11: 1 | DP11: 1 | DQ11: 1 | DR11: 1 | DS11: 1 | DT11: 1 | DU11: 1 | DV11: 1 | DW11: 1 | DX11: 1 | DY11: 1 | DZ11: 1 | EA11: 1 | EB11: 1 | EC11: 1 | ED11: 1 | EE11: 1 | EF11: 1 | EG11: 1 | EH11: 1 | EI11: 1 | EJ11: 1 | EK11: 1 | EL11: 1 | EM11: 1 | EN11: 1 | EO11: 1 | EP11: 1 | EQ11: 1 | ER11: 1 | ES11: 1 | ET11: 1 | EU11: 1 | EV11: 1 | EW11: 1 | EX11: 1 | EY11: 1 | EZ11: 1 | FA11: 1 | FB11: 1 | FC11: 1 | FD11: 1 | FE11: 1 | FF11: 1 | FG11: 1 | FH11: 1 | FI11: 1 | FJ11: 1 | FK11: 1 | FL11: 1 | FM11: 1 | FN11: 1 | FO11: 1 | FP11: 1 | FQ11: 1 | FR11: 1 | FS11: 1 | FT11: 1 | FU11: 1 | FV11: 1 | FW11: 1 | FX11: 1 | FY11: 1 | FZ11: 1 | GA11: 1 | GB11: 1 | GC11: 1 | GD11: 1 | GE11: 1 | GF11: 1 | GG11: 1 | GH11: 1 | GI11: 1 | GJ11: 1 | GK11: 1 | GL11: 1 | GM11: 1 | GN11: 1 | GO11: 1 | GP11: 1 | GQ11: 1 | GR11: 1 | GS11: 1 | GT11: 1 | GU11: 1 | GV11: 1 | GW11: 1 | GX11: 1 | GY11: 1 | GZ11: 1 | HA11: 1 | HB11: 1 | HC11: 1 | HD11: 1 | HE11: 1 | HF11: 1 | HG11: 1 | HH11: 1 | HI11: 1 | HJ11: 1 | HK11: 1 | HL11: 1 | HM11: 1 | HN11: 1 | HO11: 1 | HP11: 1 | HQ11: 1 | HR11: 1 | HS11: 1
